Workbook

Sheet הסבר
A1: מחשבון ציונים — פריימריז הדמוקרטים 2026
A3: מה יש כאן? | B3: דירוגי 51 המועמדים ב-10 נושאים (5 ממדים) ו-5 תכונות (4 ממדים), בסולם 1-5, לפי תיקי המידע.
A4: איך משתמשים? | B4: 1. פתחו את גיליון "פרמטרים" וכוונו את המשקלים (תאים כחולים) לפי ההעדפות שלכם.
B5: 2. גיליון "דירוג סופי" יתעדכן אוטומטית ויציג את המועמדים מהגבוה לנמוך.
B6: 3. בפריימריז מצביעים ל-6-8 מועמדים — קחו את הראשונים בדירוג, בכפוף לשיקולי שריונים.
A7: הנוסחה | B7: ציון נושא = ממוצע משוקלל של 5 הממדים (משקלי D1-D5).
B8: ציון נושאים כולל = ממוצע משוקלל של 10 הנושאים (משקלי הנושאים).
B9: ציון תכונות = מקביל, עם משקלי E1-E4 ומשקלי התכונות.
B10: ציון סופי = [λ×נושאים + (1-λ)×תכונות] × [1 - β×(5-ביסוס)/4]
B11: β קובע כמה "לקנוס" מועמד שהמידע עליו דל (ביסוס נמוך = בעיקר עדות עצמית).
A12: אזהרה | B12: הדירוגים הם שיפוט מנומק על סמך המקורות שנאספו ב-6.7.2026 — לא מדידה אובייקטיבית.
B13: פירוט הראיות: candidates/*.md · אמינות מקורות: 02-sources.md · שיטה: 04-scoring-method.md

Sheet פרמטרים
A1: פרמטרים אישיים — שנו את התאים הכחולים (0-10)
A3: משקלי נושאים (0-10)
A4: T1 ביטחון/חטופים | B4: 5
A5: T2 דמוקרטיה ומשפט | B5: 9
A6: T3 דת ומדינה/שוויון בנטל | B6: 10
A7: T4 הסדרה ושלום | B7: 3
A8: T5 שוויון אזרחי/שותפות | B8: 5
A9: T6 כלכלה עבודה ורווחה | B9: 5
A10: T7 חינוך ובריאות | B10: 5
A11: T8 סביבה ואקלים | B11: 3
A12: T9 שקיפות וטוהר מידות | B12: 7
A13: T10 מגדר ולהט"ב | B13: 2
A15: משקלי תכונות (0-10)
A16: C1 יושרה | B16: 6
A17: C2 חריצות וביצוע | B17: 9
A18: C3 אומץ ציבורי | B18: 8
A19: C4 חיבור ועבודה רוחבית | B19: 10
A20: C5 מקצועיות וניסיון | B20: 5
A22: משקלי ממדי נושא (D1-D5) | B22: D1 הצהרות | C22: D2 תקשורת | D22: D3 שטח | E22: D4 הצלחה | F22: D5 קרדיט
B23: 1 | C23: 1 | D23: 2 | E23: 3 | F23: 2
A25: משקלי ממדי תכונה (E1-E4) | B25: E1 עדות עצמית | C25: E2 קרדיט עמיתים | D25: E3 תקשורת | E25: E4 שטח
B26: 0.5 | C26: 2 | D26: 2 | E26: 1.5
A28: λ — משקל נושאים מול תכונות (0-1) | B28: 0.7
A29: β — קנס על ביסוס נמוך (0-0.5) | B29: 0.25

Sheet דירוגי נושאים
A1: מס' | B1: מועמד/ת | C1: ביסוס | D1: T1 D1 | E1: T1 D2 | F1: T1 D3 | G1: T1 D4 | H1: T1 D5 | I1: T2 D1 | J1: T2 D2 | K1: T2 D3 | L1: T2 D4 | M1: T2 D5 | N1: T3 D1 | O1: T3 D2 | P1: T3 D3 | Q1: T3 D4 | R1: T3 D5 | S1: T4 D1 | T1: T4 D2 | U1: T4 D3 | V1: T4 D4 | W1: T4 D5 | X1: T5 D1 | Y1: T5 D2 | Z1: T5 D3 | AA1: T5 D4 | AB1: T5 D5 | AC1: T6 D1 | AD1: T6 D2 | AE1: T6 D3 | AF1: T6 D4 | AG1: T6 D5 | AH1: T7 D1 | AI1: T7 D2 | AJ1: T7 D3 | AK1: T7 D4 | AL1: T7 D5 | AM1: T8 D1 | AN1: T8 D2 | AO1: T8 D3 | AP1: T8 D4 | AQ1: T8 D5 | AR1: T9 D1 | AS1: T9 D2 | AT1: T9 D3 | AU1: T9 D4 | AV1: T9 D5 | AW1: T10 D1 | AX1: T10 D2 | AY1: T10 D3 | AZ1: T10 D4 | BA1: T10 D5
A2: 1 | B2: משה רדמן אבוטבול | C2: 4.5 | D2: 3 | E2: 3 | F2: 3 | G2: 2 | H2: 2 | I2: 5 | J2: 5 | K2: 5 | L2: 4 | M2: 3 | N2: 1 | O2: 1 | P2: 1 | Q2: 1 | R2: 1 | S2: 3 | T2: 2 | U2: 2 | V2: 1 | W2: 1 | X2: 1 | Y2: 1 | Z2: 1 | AA2: 1 | AB2: 1 | AC2: 1 | AD2: 1 | AE2: 1 | AF2: 1 | AG2: 1 | AH2: 1 | AI2: 1 | AJ2: 1 | AK2: 1 | AL2: 1 | AM2: 1 | AN2: 1 | AO2: 1 | AP2: 1 | AQ2: 1 | AR2: 3 | AS2: 3 | AT2: 2 | AU2: 2 | AV2: 1 | AW2: 1 | AX2: 1 | AY2: 1 | AZ2: 1 | BA2: 1
A3: 2 | B3: ערן עציון | C3: 4 | D3: 4 | E3: 4 | F3: 4 | G3: 3 | H3: 2 | I3: 4 | J3: 4 | K3: 4 | L3: 3 | M3: 2 | N3: 1 | O3: 1 | P3: 1 | Q3: 1 | R3: 1 | S3: 5 | T3: 4 | U3: 4 | V3: 3 | W3: 3 | X3: 1 | Y3: 1 | Z3: 1 | AA3: 1 | AB3: 1 | AC3: 1 | AD3: 1 | AE3: 1 | AF3: 1 | AG3: 1 | AH3: 1 | AI3: 1 | AJ3: 1 | AK3: 1 | AL3: 1 | AM3: 1 | AN3: 1 | AO3: 1 | AP3: 1 | AQ3: 1 | AR3: 2 | AS3: 2 | AT3: 3 | AU3: 2 | AV3: 1 | AW3: 1 | AX3: 1 | AY3: 1 | AZ3: 1 | BA3: 1
A4: 3 | B4: מורן זר קצנשטיין | C4: 4.5 | D4: 3 | E4: 3 | F4: 4 | G4: 3 | H4: 2 | I4: 5 | J4: 4 | K4: 5 | L4: 3 | M4: 3 | N4: 4 | O4: 2 | P4: 1 | Q4: 1 | R4: 1 | S4: 1 | T4: 1 | U4: 1 | V4: 1 | W4: 1 | X4: 1 | Y4: 1 | Z4: 1 | AA4: 1 | AB4: 1 | AC4: 1 | AD4: 1 | AE4: 1 | AF4: 1 | AG4: 1 | AH4: 1 | AI4: 1 | AJ4: 1 | AK4: 1 | AL4: 1 | AM4: 1 | AN4: 1 | AO4: 1 | AP4: 1 | AQ4: 1 | AR4: 1 | AS4: 1 | AT4: 1 | AU4: 1 | AV4: 1 | AW4: 5 | AX4: 5 | AY4: 5 | AZ4: 4 | BA4: 3
A5: 4 | B5: יעל כהן־פארן | C5: 4.5 | D5: 1 | E5: 1 | F5: 1 | G5: 1 | H5: 1 | I5: 1 | J5: 1 | K5: 1 | L5: 1 | M5: 1 | N5: 2 | O5: 2 | P5: 3 | Q5: 2 | R5: 1 | S5: 1 | T5: 1 | U5: 1 | V5: 1 | W5: 1 | X5: 1 | Y5: 1 | Z5: 1 | AA5: 1 | AB5: 1 | AC5: 3 | AD5: 2 | AE5: 3 | AF5: 3 | AG5: 2 | AH5: 1 | AI5: 1 | AJ5: 1 | AK5: 1 | AL5: 1 | AM5: 5 | AN5: 4 | AO5: 5 | AP5: 4 | AQ5: 3 | AR5: 1 | AS5: 1 | AT5: 1 | AU5: 1 | AV5: 1 | AW5: 1 | AX5: 1 | AY5: 1 | AZ5: 1 | BA5: 1
A6: 5 | B6: לי הופמן אגיב | C6: 3.5 | D6: 3 | E6: 2 | F6: 3 | G6: 2 | H6: 1 | I6: 4 | J6: 3 | K6: 4 | L6: 2 | M6: 2 | N6: 1 | O6: 1 | P6: 1 | Q6: 1 | R6: 1 | S6: 1 | T6: 1 | U6: 1 | V6: 1 | W6: 1 | X6: 1 | Y6: 1 | Z6: 1 | AA6: 1 | AB6: 1 | AC6: 1 | AD6: 1 | AE6: 1 | AF6: 1 | AG6: 1 | AH6: 1 | AI6: 1 | AJ6: 1 | AK6: 1 | AL6: 1 | AM6: 1 | AN6: 1 | AO6: 1 | AP6: 1 | AQ6: 1 | AR6: 1 | AS6: 1 | AT6: 1 | AU6: 1 | AV6: 1 | AW6: 4 | AX6: 2 | AY6: 4 | AZ6: 3 | BA6: 2
A7: 6 | B7: רם שפע | C7: 5 | D7: 4 | E7: 4 | F7: 5 | G7: 4 | H7: 4 | I7: 1 | J7: 1 | K7: 1 | L7: 1 | M7: 1 | N7: 1 | O7: 1 | P7: 1 | Q7: 1 | R7: 1 | S7: 1 | T7: 1 | U7: 1 | V7: 1 | W7: 1 | X7: 1 | Y7: 1 | Z7: 1 | AA7: 1 | AB7: 1 | AC7: 3 | AD7: 2 | AE7: 3 | AF7: 3 | AG7: 2 | AH7: 5 | AI7: 4 | AJ7: 5 | AK7: 4 | AL7: 3 | AM7: 1 | AN7: 1 | AO7: 1 | AP7: 1 | AQ7: 1 | AR7: 1 | AS7: 1 | AT7: 1 | AU7: 1 | AV7: 1 | AW7: 1 | AX7: 1 | AY7: 1 | AZ7: 1 | BA7: 1
A8: 7 | B8: יריב אופנהיימר | C8: 4 | D8: 1 | E8: 1 | F8: 1 | G8: 1 | H8: 1 | I8: 4 | J8: 4 | K8: 4 | L8: 2 | M8: 2 | N8: 1 | O8: 1 | P8: 1 | Q8: 1 | R8: 1 | S8: 5 | T8: 5 | U8: 5 | V8: 3 | W8: 3 | X8: 3 | Y8: 4 | Z8: 4 | AA8: 2 | AB8: 2 | AC8: 1 | AD8: 1 | AE8: 1 | AF8: 1 | AG8: 1 | AH8: 1 | AI8: 1 | AJ8: 1 | AK8: 1 | AL8: 1 | AM8: 1 | AN8: 1 | AO8: 1 | AP8: 1 | AQ8: 1 | AR8: 1 | AS8: 1 | AT8: 1 | AU8: 1 | AV8: 1 | AW8: 1 | AX8: 1 | AY8: 1 | AZ8: 1 | BA8: 1
A9: 8 | B9: אוליביה עמנואל דה לם | C9: 2 | D9: 1 | E9: 1 | F9: 1 | G9: 1 | H9: 1 | I9: 1 | J9: 1 | K9: 1 | L9: 1 | M9: 1 | N9: 1 | O9: 1 | P9: 1 | Q9: 1 | R9: 1 | S9: 1 | T9: 1 | U9: 1 | V9: 1 | W9: 1 | X9: 1 | Y9: 1 | Z9: 1 | AA9: 1 | AB9: 1 | AC9: 1 | AD9: 1 | AE9: 1 | AF9: 1 | AG9: 1 | AH9: 1 | AI9: 1 | AJ9: 1 | AK9: 1 | AL9: 1 | AM9: 1 | AN9: 1 | AO9: 1 | AP9: 1 | AQ9: 1 | AR9: 1 | AS9: 1 | AT9: 1 | AU9: 1 | AV9: 1 | AW9: 1 | AX9: 1 | AY9: 1 | AZ9: 1 | BA9: 1
A10: 9 | B10: נאור נרקיס | C10: 4.5 | D10: 1 | E10: 1 | F10: 1 | G10: 1 | H10: 1 | I10: 3 | J10: 3 | K10: 2 | L10: 2 | M10: 2 | N10: 5 | O10: 5 | P10: 5 | Q10: 5 | R10: 2 | S10: 1 | T10: 1 | U10: 1 | V10: 1 | W10: 1 | X10: 1 | Y10: 1 | Z10: 1 | AA10: 1 | AB10: 1 | AC10: 1 | AD10: 1 | AE10: 1 | AF10: 1 | AG10: 1 | AH10: 1 | AI10: 1 | AJ10: 1 | AK10: 1 | AL10: 1 | AM10: 1 | AN10: 1 | AO10: 1 | AP10: 1 | AQ10: 1 | AR10: 1 | AS10: 1 | AT10: 1 | AU10: 1 | AV10: 1 | AW10: 1 | AX10: 1 | AY10: 1 | AZ10: 1 | BA10: 1
A11: 10 | B11: מהרטה ברוך־רון | C11: 4 | D11: 1 | E11: 1 | F11: 1 | G11: 1 | H11: 1 | I11: 1 | J11: 1 | K11: 1 | L11: 1 | M11: 1 | N11: 1 | O11: 1 | P11: 1 | Q11: 1 | R11: 1 | S11: 1 | T11: 1 | U11: 1 | V11: 1 | W11: 1 | X11: 5 | Y11: 3 | Z11: 4 | AA11: 3 | AB11: 2 | AC11: 1 | AD11: 1 | AE11: 1 | AF11: 1 | AG11: 1 | AH11: 1 | AI11: 1 | AJ11: 1 | AK11: 1 | AL11: 1 | AM11: 1 | AN11: 1 | AO11: 1 | AP11: 1 | AQ11: 1 | AR11: 1 | AS11: 1 | AT11: 1 | AU11: 1 | AV11: 1 | AW11: 4 | AX11: 2 | AY11: 3 | AZ11: 3 | BA11: 2
A12: 11 | B12: עמרי רונן | C12: 4 | D12: 3 | E12: 2 | F12: 4 | G12: 3 | H12: 1 | I12: 4 | J12: 3 | K12: 4 | L12: 2 | M12: 2 | N12: 1 | O12: 1 | P12: 1 | Q12: 1 | R12: 1 | S12: 1 | T12: 1 | U12: 1 | V12: 1 | W12: 1 | X12: 3 | Y12: 1 | Z12: 2 | AA12: 1 | AB12: 1 | AC12: 1 | AD12: 1 | AE12: 1 | AF12: 1 | AG12: 1 | AH12: 1 | AI12: 1 | AJ12: 1 | AK12: 1 | AL12: 1 | AM12: 1 | AN12: 1 | AO12: 1 | AP12: 1 | AQ12: 1 | AR12: 1 | AS12: 1 | AT12: 1 | AU12: 1 | AV12: 1 | AW12: 1 | AX12: 1 | AY12: 1 | AZ12: 1 | BA12: 1
A13: 12 | B13: ירון ניב | C13: 4 | D13: 1 | E13: 1 | F13: 1 | G13: 1 | H13: 1 | I13: 1 | J13: 1 | K13: 1 | L13: 1 | M13: 1 | N13: 1 | O13: 1 | P13: 1 | Q13: 1 | R13: 1 | S13: 1 | T13: 1 | U13: 1 | V13: 1 | W13: 1 | X13: 1 | Y13: 1 | Z13: 1 | AA13: 1 | AB13: 1 | AC13: 1 | AD13: 1 | AE13: 1 | AF13: 1 | AG13: 1 | AH13: 5 | AI13: 3 | AJ13: 4 | AK13: 4 | AL13: 3 | AM13: 1 | AN13: 1 | AO13: 1 | AP13: 1 | AQ13: 1 | AR13: 1 | AS13: 1 | AT13: 1 | AU13: 1 | AV13: 1 | AW13: 1 | AX13: 1 | AY13: 1 | AZ13: 1 | BA13: 1
... A52: 51 | B52: נמרוד שפר | C52: 4 | D52: 5 | E52: 3 | F52: 4 | G52: 4 | H52: 2 | I52: 1 | J52: 1 | K52: 1 | L52: 1 | M52: 1 | N52: 1 | O52: 1 | P52: 1 | Q52: 1 | R52: 1 | S52: 1 | T52: 1 | U52: 1 | V52: 1 | W52: 1 | X52: 1 | Y52: 1 | Z52: 1 | AA52: 1 | AB52: 1 | AC52: 3 | AD52: 2 | AE52: 3 | AF52: 3 | AG52: 2 | AH52: 1 | AI52: 1 | AJ52: 1 | AK52: 1 | AL52: 1 | AM52: 1 | AN52: 1 | AO52: 1 | AP52: 1 | AQ52: 1 | AR52: 1 | AS52: 1 | AT52: 1 | AU52: 1 | AV52: 1 | AW52: 1 | AX52: 1 | AY52: 1 | AZ52: 1 | BA52: 1

Sheet דירוגי תכונות
A1: מס' | B1: מועמד/ת | C1: C1 E1 | D1: C1 E2 | E1: C1 E3 | F1: C1 E4 | G1: C2 E1 | H1: C2 E2 | I1: C2 E3 | J1: C2 E4 | K1: C3 E1 | L1: C3 E2 | M1: C3 E3 | N1: C3 E4 | O1: C4 E1 | P1: C4 E2 | Q1: C4 E3 | R1: C4 E4 | S1: C5 E1 | T1: C5 E2 | U1: C5 E3 | V1: C5 E4
A2: 1 | B2: משה רדמן אבוטבול | C2: 4 | D2: 2 | E2: 2 | F2: 2 | G2: 4 | H2: 3 | I2: 4 | J2: 5 | K2: 5 | L2: 3 | M2: 5 | N2: 5 | O2: 4 | P2: 2 | Q2: 3 | R2: 4 | S2: 3 | T2: 2 | U2: 3 | V2: 4
A3: 2 | B3: ערן עציון | C3: 4 | D3: 2 | E3: 3 | F3: 3 | G3: 4 | H3: 2 | I3: 3 | J3: 4 | K3: 4 | L3: 2 | M3: 3 | N3: 3 | O3: 3 | P3: 2 | Q3: 3 | R3: 4 | S3: 5 | T3: 3 | U3: 4 | V3: 5
A4: 3 | B4: מורן זר קצנשטיין | C4: 4 | D4: 2 | E4: 4 | F4: 4 | G4: 4 | H4: 3 | I4: 4 | J4: 4 | K4: 5 | L4: 3 | M4: 4 | N4: 5 | O4: 5 | P4: 3 | Q4: 4 | R4: 5 | S4: 4 | T4: 3 | U4: 3 | V4: 4
A5: 4 | B5: יעל כהן־פארן | C5: 4 | D5: 2 | E5: 3 | F5: 3 | G5: 4 | H5: 2 | I5: 3 | J5: 4 | K5: 3 | L5: 2 | M5: 3 | N5: 3 | O5: 4 | P5: 2 | Q5: 3 | R5: 4 | S5: 4 | T5: 3 | U5: 3 | V5: 4
A6: 5 | B6: לי הופמן אגיב | C6: 3 | D6: 1 | E6: 2 | F6: 2 | G6: 3 | H6: 2 | I6: 3 | J6: 3 | K6: 3 | L6: 2 | M6: 3 | N6: 3 | O6: 3 | P6: 1 | Q6: 2 | R6: 2 | S6: 3 | T6: 1 | U6: 2 | V6: 2
A7: 6 | B7: רם שפע | C7: 4 | D7: 2 | E7: 3 | F7: 3 | G7: 4 | H7: 3 | I7: 4 | J7: 5 | K7: 3 | L7: 2 | M7: 3 | N7: 3 | O7: 4 | P7: 3 | Q7: 4 | R7: 5 | S7: 4 | T7: 4 | U7: 4 | V7: 4
A8: 7 | B8: יריב אופנהיימר | C8: 4 | D8: 2 | E8: 3 | F8: 4 | G8: 4 | H8: 2 | I8: 4 | J8: 5 | K8: 5 | L8: 3 | M8: 4 | N8: 5 | O8: 3 | P8: 2 | Q8: 2 | R8: 3 | S8: 4 | T8: 2 | U8: 3 | V8: 4
A9: 8 | B9: אוליביה עמנואל דה לם | C9: 5 | D9: 1 | E9: 1 | F9: 2 | G9: 3 | H9: 1 | I9: 2 | J9: 2 | K9: 3 | L9: 1 | M9: 2 | N9: 2 | O9: 3 | P9: 1 | Q9: 2 | R9: 2 | S9: 3 | T9: 1 | U9: 2 | V9: 2
A10: 9 | B10: נאור נרקיס | C10: 4 | D10: 2 | E10: 2 | F10: 3 | G10: 5 | H10: 2 | I10: 4 | J10: 5 | K10: 5 | L10: 2 | M10: 4 | N10: 5 | O10: 2 | P10: 1 | Q10: 1 | R10: 2 | S10: 3 | T10: 2 | U10: 3 | V10: 3
A11: 10 | B11: מהרטה ברוך־רון | C11: 4 | D11: 2 | E11: 3 | F11: 3 | G11: 4 | H11: 2 | I11: 3 | J11: 4 | K11: 4 | L11: 2 | M11: 3 | N11: 4 | O11: 4 | P11: 2 | Q11: 3 | R11: 4 | S11: 4 | T11: 2 | U11: 3 | V11: 4
A12: 11 | B12: עמרי רונן | C12: 3 | D12: 2 | E12: 3 | F12: 3 | G12: 3 | H12: 1 | I12: 3 | J12: 3 | K12: 4 | L12: 2 | M12: 3 | N12: 4 | O12: 3 | P12: 1 | Q12: 2 | R12: 2 | S12: 3 | T12: 1 | U12: 2 | V12: 2
A13: 12 | B13: ירון ניב | C13: 4 | D13: 2 | E13: 2 | F13: 3 | G13: 4 | H13: 2 | I13: 2 | J13: 4 | K13: 3 | L13: 1 | M13: 2 | N13: 2 | O13: 3 | P13: 2 | Q13: 2 | R13: 3 | S13: 5 | T13: 3 | U13: 3 | V13: 5
... A52: 51 | B52: נמרוד שפר | C52: 3 | D52: 1 | E52: 1 | F52: 2 | G52: 4 | H52: 2 | I52: 3 | J52: 4 | K52: 3 | L52: 2 | M52: 3 | N52: 3 | O52: 3 | P52: 2 | Q52: 2 | R52: 3 | S52: 5 | T52: 3 | U52: 4 | V52: 5

Sheet חישוב
A1: מס' | B1: מועמד/ת | C1: T1 | D1: T2 | E1: T3 | F1: T4 | G1: T5 | H1: T6 | I1: T7 | J1: T8 | K1: T9 | L1: T10 | M1: ציון נושאים | N1: C1 | O1: C2 | P1: C3 | Q1: C4 | R1: C5 | S1: ציון תכונות | T1: ביסוס | U1: ציון סופי (1-5) | V1: ציון סופי (0-100) | W1: שובר שוויון | X1: מקום
A2: 1 | B2: ='דירוגי נושאים'!B2 | C2: =SUMPRODUCT('דירוגי נושאים'!D2:H2,פרמטרים!$B$23:$F$23)/SUM(פרמטרים!$B$23:$F$23) | D2: =SUMPRODUCT('דירוגי נושאים'!I2:M2,פרמטרים!$B$23:$F$23)/SUM(פרמטרים!$B$23:$F$23) | E2: =SUMPRODUCT('דירוגי נושאים'!N2:R2,פרמטרים!$B$23:$F$23)/SUM(פרמטרים!$B$23:$F$23) | F2: =SUMPRODUCT('דירוגי נושאים'!S2:W2,פרמטרים!$B$23:$F$23)/SUM(פרמטרים!$B$23:$F$23) | G2: =SUMPRODUCT('דירוגי נושאים'!X2:AB2,פרמטרים!$B$23:$F$23)/SUM(פרמטרים!$B$23:$F$23) | H2: =SUMPRODUCT('דירוגי נושאים'!AC2:AG2,פרמטרים!$B$23:$F$23)/SUM(פרמטרים!$B$23:$F$23) | I2: =SUMPRODUCT('דירוגי נושאים'!AH2:AL2,פרמטרים!$B$23:$F$23)/SUM(פרמטרים!$B$23:$F$23) | J2: =SUMPRODUCT('דירוגי נושאים'!AM2:AQ2,פרמטרים!$B$23:$F$23)/SUM(פרמטרים!$B$23:$F$23) | K2: =SUMPRODUCT('דירוגי נושאים'!AR2:AV2,פרמטרים!$B$23:$F$23)/SUM(פרמטרים!$B$23:$F$23) | L2: =SUMPRODUCT('דירוגי נושאים'!AW2:BA2,פרמטרים!$B$23:$F$23)/SUM(פרמטרים!$B$23:$F$23) | M2: =(C2*פרמטרים!$B$4+D2*פרמטרים!$B$5+E2*פרמטרים!$B$6+F2*פרמטרים!$B$7+G2*פרמטרים!$B$8+H2*פרמטרים!$B$9+I2*פרמטרים!$B$10+J2*פרמטרים!$B$11+K2*פרמטרים!$B$12+L2*פרמטרים!$B$13)/SUM(פרמטרים!$B$4:$B$13) | N2: =SUMPRODUCT('דירוגי תכונות'!C2:F2,פרמטרים!$B$26:$E$26)/SUM(פרמטרים!$B$26:$E$26) | O2: =SUMPRODUCT('דירוגי תכונות'!G2:J2,פרמטרים!$B$26:$E$26)/SUM(פרמטרים!$B$26:$E$26) | P2: =SUMPRODUCT('דירוגי תכונות'!K2:N2,פרמטרים!$B$26:$E$26)/SUM(פרמטרים!$B$26:$E$26) | Q2: =SUMPRODUCT('דירוגי תכונות'!O2:R2,פרמטרים!$B$26:$E$26)/SUM(פרמטרים!$B$26:$E$26) | R2: =SUMPRODUCT('דירוגי תכונות'!S2:V2,פרמטרים!$B$26:$E$26)/SUM(פרמטרים!$B$26:$E$26) | S2: =(N2*פרמטרים!$B$16+O2*פרמטרים!$B$17+P2*פרמטרים!$B$18+Q2*פרמטרים!$B$19+R2*פרמטרים!$B$20)/SUM(פרמטרים!$B$16:$B$20) | T2: ='דירוגי נושאים'!C2 | U2: =(פרמטרים!$B$28*M2+(1-פרמטרים!$B$28)*S2)*(1-פרמטרים!$B$29*(5-T2)/4) | V2: =(U2-1)/4*100 | W2: =U2+ROW()/10000000 | X2: =RANK(W2,$W$2:$W$52)
A3: 2 | B3: ='דירוגי נושאים'!B3 | C3: =SUMPRODUCT('דירוגי נושאים'!D3:H3,פרמטרים!$B$23:$F$23)/SUM(פרמטרים!$B$23:$F$23) | D3: =SUMPRODUCT('דירוגי נושאים'!I3:M3,פרמטרים!$B$23:$F$23)/SUM(פרמטרים!$B$23:$F$23) | E3: =SUMPRODUCT('דירוגי נושאים'!N3:R3,פרמטרים!$B$23:$F$23)/SUM(פרמטרים!$B$23:$F$23) | F3: =SUMPRODUCT('דירוגי נושאים'!S3:W3,פרמטרים!$B$23:$F$23)/SUM(פרמטרים!$B$23:$F$23) | G3: =SUMPRODUCT('דירוגי נושאים'!X3:AB3,פרמטרים!$B$23:$F$23)/SUM(פרמטרים!$B$23:$F$23) | H3: =SUMPRODUCT('דירוגי נושאים'!AC3:AG3,פרמטרים!$B$23:$F$23)/SUM(פרמטרים!$B$23:$F$23) | I3: =SUMPRODUCT('דירוגי נושאים'!AH3:AL3,פרמטרים!$B$23:$F$23)/SUM(פרמטרים!$B$23:$F$23) | J3: =SUMPRODUCT('דירוגי נושאים'!AM3:AQ3,פרמטרים!$B$23:$F$23)/SUM(פרמטרים!$B$23:$F$23) | K3: =SUMPRODUCT('דירוגי נושאים'!AR3:AV3,פרמטרים!$B$23:$F$23)/SUM(פרמטרים!$B$23:$F$23) | L3: =SUMPRODUCT('דירוגי נושאים'!AW3:BA3,פרמטרים!$B$23:$F$23)/SUM(פרמטרים!$B$23:$F$23) | M3: =(C3*פרמטרים!$B$4+D3*פרמטרים!$B$5+E3*פרמטרים!$B$6+F3*פרמטרים!$B$7+G3*פרמטרים!$B$8+H3*פרמטרים!$B$9+I3*פרמטרים!$B$10+J3*פרמטרים!$B$11+K3*פרמטרים!$B$12+L3*פרמטרים!$B$13)/SUM(פרמטרים!$B$4:$B$13) | N3: =SUMPRODUCT('דירוגי תכונות'!C3:F3,פרמטרים!$B$26:$E$26)/SUM(פרמטרים!$B$26:$E$26) | O3: =SUMPRODUCT('דירוגי תכונות'!G3:J3,פרמטרים!$B$26:$E$26)/SUM(פרמטרים!$B$26:$E$26) | P3: =SUMPRODUCT('דירוגי תכונות'!K3:N3,פרמטרים!$B$26:$E$26)/SUM(פרמטרים!$B$26:$E$26) | Q3: =SUMPRODUCT('דירוגי תכונות'!O3:R3,פרמטרים!$B$26:$E$26)/SUM(פרמטרים!$B$26:$E$26) | R3: =SUMPRODUCT('דירוגי תכונות'!S3:V3,פרמטרים!$B$26:$E$26)/SUM(פרמטרים!$B$26:$E$26) | S3: =(N3*פרמטרים!$B$16+O3*פרמטרים!$B$17+P3*פרמטרים!$B$18+Q3*פרמטרים!$B$19+R3*פרמטרים!$B$20)/SUM(פרמטרים!$B$16:$B$20) | T3: ='דירוגי נושאים'!C3 | U3: =(פרמטרים!$B$28*M3+(1-פרמטרים!$B$28)*S3)*(1-פרמטרים!$B$29*(5-T3)/4) | V3: =(U3-1)/4*100 | W3: =U3+ROW()/10000000 | X3: =RANK(W3,$W$2:$W$52)
A4: 3 | B4: ='דירוגי נושאים'!B4 | C4: =SUMPRODUCT('דירוגי נושאים'!D4:H4,פרמטרים!$B$23:$F$23)/SUM(פרמטרים!$B$23:$F$23) | D4: =SUMPRODUCT('דירוגי נושאים'!I4:M4,פרמטרים!$B$23:$F$23)/SUM(פרמטרים!$B$23:$F$23) | E4: =SUMPRODUCT('דירוגי נושאים'!N4:R4,פרמטרים!$B$23:$F$23)/SUM(פרמטרים!$B$23:$F$23) | F4: =SUMPRODUCT('דירוגי נושאים'!S4:W4,פרמטרים!$B$23:$F$23)/SUM(פרמטרים!$B$23:$F$23) | G4: =SUMPRODUCT('דירוגי נושאים'!X4:AB4,פרמטרים!$B$23:$F$23)/SUM(פרמטרים!$B$23:$F$23) | H4: =SUMPRODUCT('דירוגי נושאים'!AC4:AG4,פרמטרים!$B$23:$F$23)/SUM(פרמטרים!$B$23:$F$23) | I4: =SUMPRODUCT('דירוגי נושאים'!AH4:AL4,פרמטרים!$B$23:$F$23)/SUM(פרמטרים!$B$23:$F$23) | J4: =SUMPRODUCT('דירוגי נושאים'!AM4:AQ4,פרמטרים!$B$23:$F$23)/SUM(פרמטרים!$B$23:$F$23) | K4: =SUMPRODUCT('דירוגי נושאים'!AR4:AV4,פרמטרים!$B$23:$F$23)/SUM(פרמטרים!$B$23:$F$23) | L4: =SUMPRODUCT('דירוגי נושאים'!AW4:BA4,פרמטרים!$B$23:$F$23)/SUM(פרמטרים!$B$23:$F$23) | M4: =(C4*פרמטרים!$B$4+D4*פרמטרים!$B$5+E4*פרמטרים!$B$6+F4*פרמטרים!$B$7+G4*פרמטרים!$B$8+H4*פרמטרים!$B$9+I4*פרמטרים!$B$10+J4*פרמטרים!$B$11+K4*פרמטרים!$B$12+L4*פרמטרים!$B$13)/SUM(פרמטרים!$B$4:$B$13) | N4: =SUMPRODUCT('דירוגי תכונות'!C4:F4,פרמטרים!$B$26:$E$26)/SUM(פרמטרים!$B$26:$E$26) | O4: =SUMPRODUCT('דירוגי תכונות'!G4:J4,פרמטרים!$B$26:$E$26)/SUM(פרמטרים!$B$26:$E$26) | P4: =SUMPRODUCT('דירוגי תכונות'!K4:N4,פרמטרים!$B$26:$E$26)/SUM(פרמטרים!$B$26:$E$26) | Q4: =SUMPRODUCT('דירוגי תכונות'!O4:R4,פרמטרים!$B$26:$E$26)/SUM(פרמטרים!$B$26:$E$26) | R4: =SUMPRODUCT('דירוגי תכונות'!S4:V4,פרמטרים!$B$26:$E$26)/SUM(פרמטרים!$B$26:$E$26) | S4: =(N4*פרמטרים!$B$16+O4*פרמטרים!$B$17+P4*פרמטרים!$B$18+Q4*פרמטרים!$B$19+R4*פרמטרים!$B$20)/SUM(פרמטרים!$B$16:$B$20) | T4: ='דירוגי נושאים'!C4 | U4: =(פרמטרים!$B$28*M4+(1-פרמטרים!$B$28)*S4)*(1-פרמטרים!$B$29*(5-T4)/4) | V4: =(U4-1)/4*100 | W4: =U4+ROW()/10000000 | X4: =RANK(W4,$W$2:$W$52)
A5: 4 | B5: ='דירוגי נושאים'!B5 | C5: =SUMPRODUCT('דירוגי נושאים'!D5:H5,פרמטרים!$B$23:$F$23)/SUM(פרמטרים!$B$23:$F$23) | D5: =SUMPRODUCT('דירוגי נושאים'!I5:M5,פרמטרים!$B$23:$F$23)/SUM(פרמטרים!$B$23:$F$23) | E5: =SUMPRODUCT('דירוגי נושאים'!N5:R5,פרמטרים!$B$23:$F$23)/SUM(פרמטרים!$B$23:$F$23) | F5: =SUMPRODUCT('דירוגי נושאים'!S5:W5,פרמטרים!$B$23:$F$23)/SUM(פרמטרים!$B$23:$F$23) | G5: =SUMPRODUCT('דירוגי נושאים'!X5:AB5,פרמטרים!$B$23:$F$23)/SUM(פרמטרים!$B$23:$F$23) | H5: =SUMPRODUCT('דירוגי נושאים'!AC5:AG5,פרמטרים!$B$23:$F$23)/SUM(פרמטרים!$B$23:$F$23) | I5: =SUMPRODUCT('דירוגי נושאים'!AH5:AL5,פרמטרים!$B$23:$F$23)/SUM(פרמטרים!$B$23:$F$23) | J5: =SUMPRODUCT('דירוגי נושאים'!AM5:AQ5,פרמטרים!$B$23:$F$23)/SUM(פרמטרים!$B$23:$F$23) | K5: =SUMPRODUCT('דירוגי נושאים'!AR5:AV5,פרמטרים!$B$23:$F$23)/SUM(פרמטרים!$B$23:$F$23) | L5: =SUMPRODUCT('דירוגי נושאים'!AW5:BA5,פרמטרים!$B$23:$F$23)/SUM(פרמטרים!$B$23:$F$23) | M5: =(C5*פרמטרים!$B$4+D5*פרמטרים!$B$5+E5*פרמטרים!$B$6+F5*פרמטרים!$B$7+G5*פרמטרים!$B$8+H5*פרמטרים!$B$9+I5*פרמטרים!$B$10+J5*פרמטרים!$B$11+K5*פרמטרים!$B$12+L5*פרמטרים!$B$13)/SUM(פרמטרים!$B$4:$B$13) | N5: =SUMPRODUCT('דירוגי תכונות'!C5:F5,פרמטרים!$B$26:$E$26)/SUM(פרמטרים!$B$26:$E$26) | O5: =SUMPRODUCT('דירוגי תכונות'!G5:J5,פרמטרים!$B$26:$E$26)/SUM(פרמטרים!$B$26:$E$26) | P5: =SUMPRODUCT('דירוגי תכונות'!K5:N5,פרמטרים!$B$26:$E$26)/SUM(פרמטרים!$B$26:$E$26) | Q5: =SUMPRODUCT('דירוגי תכונות'!O5:R5,פרמטרים!$B$26:$E$26)/SUM(פרמטרים!$B$26:$E$26) | R5: =SUMPRODUCT('דירוגי תכונות'!S5:V5,פרמטרים!$B$26:$E$26)/SUM(פרמטרים!$B$26:$E$26) | S5: =(N5*פרמטרים!$B$16+O5*פרמטרים!$B$17+P5*פרמטרים!$B$18+Q5*פרמטרים!$B$19+R5*פרמטרים!$B$20)/SUM(פרמטרים!$B$16:$B$20) | T5: ='דירוגי נושאים'!C5 | U5: =(פרמטרים!$B$28*M5+(1-פרמטרים!$B$28)*S5)*(1-פרמטרים!$B$29*(5-T5)/4) | V5: =(U5-1)/4*100 | W5: =U5+ROW()/10000000 | X5: =RANK(W5,$W$2:$W$52)
A6: 5 | B6: ='דירוגי נושאים'!B6 | C6: =SUMPRODUCT('דירוגי נושאים'!D6:H6,פרמטרים!$B$23:$F$23)/SUM(פרמטרים!$B$23:$F$23) | D6: =SUMPRODUCT('דירוגי נושאים'!I6:M6,פרמטרים!$B$23:$F$23)/SUM(פרמטרים!$B$23:$F$23) | E6: =SUMPRODUCT('דירוגי נושאים'!N6:R6,פרמטרים!$B$23:$F$23)/SUM(פרמטרים!$B$23:$F$23) | F6: =SUMPRODUCT('דירוגי נושאים'!S6:W6,פרמטרים!$B$23:$F$23)/SUM(פרמטרים!$B$23:$F$23) | G6: =SUMPRODUCT('דירוגי נושאים'!X6:AB6,פרמטרים!$B$23:$F$23)/SUM(פרמטרים!$B$23:$F$23) | H6: =SUMPRODUCT('דירוגי נושאים'!AC6:AG6,פרמטרים!$B$23:$F$23)/SUM(פרמטרים!$B$23:$F$23) | I6: =SUMPRODUCT('דירוגי נושאים'!AH6:AL6,פרמטרים!$B$23:$F$23)/SUM(פרמטרים!$B$23:$F$23) | J6: =SUMPRODUCT('דירוגי נושאים'!AM6:AQ6,פרמטרים!$B$23:$F$23)/SUM(פרמטרים!$B$23:$F$23) | K6: =SUMPRODUCT('דירוגי נושאים'!AR6:AV6,פרמטרים!$B$23:$F$23)/SUM(פרמטרים!$B$23:$F$23) | L6: =SUMPRODUCT('דירוגי נושאים'!AW6:BA6,פרמטרים!$B$23:$F$23)/SUM(פרמטרים!$B$23:$F$23) | M6: =(C6*פרמטרים!$B$4+D6*פרמטרים!$B$5+E6*פרמטרים!$B$6+F6*פרמטרים!$B$7+G6*פרמטרים!$B$8+H6*פרמטרים!$B$9+I6*פרמטרים!$B$10+J6*פרמטרים!$B$11+K6*פרמטרים!$B$12+L6*פרמטרים!$B$13)/SUM(פרמטרים!$B$4:$B$13) | N6: =SUMPRODUCT('דירוגי תכונות'!C6:F6,פרמטרים!$B$26:$E$26)/SUM(פרמטרים!$B$26:$E$26) | O6: =SUMPRODUCT('דירוגי תכונות'!G6:J6,פרמטרים!$B$26:$E$26)/SUM(פרמטרים!$B$26:$E$26) | P6: =SUMPRODUCT('דירוגי תכונות'!K6:N6,פרמטרים!$B$26:$E$26)/SUM(פרמטרים!$B$26:$E$26) | Q6: =SUMPRODUCT('דירוגי תכונות'!O6:R6,פרמטרים!$B$26:$E$26)/SUM(פרמטרים!$B$26:$E$26) | R6: =SUMPRODUCT('דירוגי תכונות'!S6:V6,פרמטרים!$B$26:$E$26)/SUM(פרמטרים!$B$26:$E$26) | S6: =(N6*פרמטרים!$B$16+O6*פרמטרים!$B$17+P6*פרמטרים!$B$18+Q6*פרמטרים!$B$19+R6*פרמטרים!$B$20)/SUM(פרמטרים!$B$16:$B$20) | T6: ='דירוגי נושאים'!C6 | U6: =(פרמטרים!$B$28*M6+(1-פרמטרים!$B$28)*S6)*(1-פרמטרים!$B$29*(5-T6)/4) | V6: =(U6-1)/4*100 | W6: =U6+ROW()/10000000 | X6: =RANK(W6,$W$2:$W$52)
A7: 6 | B7: ='דירוגי נושאים'!B7 | C7: =SUMPRODUCT('דירוגי נושאים'!D7:H7,פרמטרים!$B$23:$F$23)/SUM(פרמטרים!$B$23:$F$23) | D7: =SUMPRODUCT('דירוגי נושאים'!I7:M7,פרמטרים!$B$23:$F$23)/SUM(פרמטרים!$B$23:$F$23) | E7: =SUMPRODUCT('דירוגי נושאים'!N7:R7,פרמטרים!$B$23:$F$23)/SUM(פרמטרים!$B$23:$F$23) | F7: =SUMPRODUCT('דירוגי נושאים'!S7:W7,פרמטרים!$B$23:$F$23)/SUM(פרמטרים!$B$23:$F$23) | G7: =SUMPRODUCT('דירוגי נושאים'!X7:AB7,פרמטרים!$B$23:$F$23)/SUM(פרמטרים!$B$23:$F$23) | H7: =SUMPRODUCT('דירוגי נושאים'!AC7:AG7,פרמטרים!$B$23:$F$23)/SUM(פרמטרים!$B$23:$F$23) | I7: =SUMPRODUCT('דירוגי נושאים'!AH7:AL7,פרמטרים!$B$23:$F$23)/SUM(פרמטרים!$B$23:$F$23) | J7: =SUMPRODUCT('דירוגי נושאים'!AM7:AQ7,פרמטרים!$B$23:$F$23)/SUM(פרמטרים!$B$23:$F$23) | K7: =SUMPRODUCT('דירוגי נושאים'!AR7:AV7,פרמטרים!$B$23:$F$23)/SUM(פרמטרים!$B$23:$F$23) | L7: =SUMPRODUCT('דירוגי נושאים'!AW7:BA7,פרמטרים!$B$23:$F$23)/SUM(פרמטרים!$B$23:$F$23) | M7: =(C7*פרמטרים!$B$4+D7*פרמטרים!$B$5+E7*פרמטרים!$B$6+F7*פרמטרים!$B$7+G7*פרמטרים!$B$8+H7*פרמטרים!$B$9+I7*פרמטרים!$B$10+J7*פרמטרים!$B$11+K7*פרמטרים!$B$12+L7*פרמטרים!$B$13)/SUM(פרמטרים!$B$4:$B$13) | N7: =SUMPRODUCT('דירוגי תכונות'!C7:F7,פרמטרים!$B$26:$E$26)/SUM(פרמטרים!$B$26:$E$26) | O7: =SUMPRODUCT('דירוגי תכונות'!G7:J7,פרמטרים!$B$26:$E$26)/SUM(פרמטרים!$B$26:$E$26) | P7: =SUMPRODUCT('דירוגי תכונות'!K7:N7,פרמטרים!$B$26:$E$26)/SUM(פרמטרים!$B$26:$E$26) | Q7: =SUMPRODUCT('דירוגי תכונות'!O7:R7,פרמטרים!$B$26:$E$26)/SUM(פרמטרים!$B$26:$E$26) | R7: =SUMPRODUCT('דירוגי תכונות'!S7:V7,פרמטרים!$B$26:$E$26)/SUM(פרמטרים!$B$26:$E$26) | S7: =(N7*פרמטרים!$B$16+O7*פרמטרים!$B$17+P7*פרמטרים!$B$18+Q7*פרמטרים!$B$19+R7*פרמטרים!$B$20)/SUM(פרמטרים!$B$16:$B$20) | T7: ='דירוגי נושאים'!C7 | U7: =(פרמטרים!$B$28*M7+(1-פרמטרים!$B$28)*S7)*(1-פרמטרים!$B$29*(5-T7)/4) | V7: =(U7-1)/4*100 | W7: =U7+ROW()/10000000 | X7: =RANK(W7,$W$2:$W$52)
A8: 7 | B8: ='דירוגי נושאים'!B8 | C8: =SUMPRODUCT('דירוגי נושאים'!D8:H8,פרמטרים!$B$23:$F$23)/SUM(פרמטרים!$B$23:$F$23) | D8: =SUMPRODUCT('דירוגי נושאים'!I8:M8,פרמטרים!$B$23:$F$23)/SUM(פרמטרים!$B$23:$F$23) | E8: =SUMPRODUCT('דירוגי נושאים'!N8:R8,פרמטרים!$B$23:$F$23)/SUM(פרמטרים!$B$23:$F$23) | F8: =SUMPRODUCT('דירוגי נושאים'!S8:W8,פרמטרים!$B$23:$F$23)/SUM(פרמטרים!$B$23:$F$23) | G8: =SUMPRODUCT('דירוגי נושאים'!X8:AB8,פרמטרים!$B$23:$F$23)/SUM(פרמטרים!$B$23:$F$23) | H8: =SUMPRODUCT('דירוגי נושאים'!AC8:AG8,פרמטרים!$B$23:$F$23)/SUM(פרמטרים!$B$23:$F$23) | I8: =SUMPRODUCT('דירוגי נושאים'!AH8:AL8,פרמטרים!$B$23:$F$23)/SUM(פרמטרים!$B$23:$F$23) | J8: =SUMPRODUCT('דירוגי נושאים'!AM8:AQ8,פרמטרים!$B$23:$F$23)/SUM(פרמטרים!$B$23:$F$23) | K8: =SUMPRODUCT('דירוגי נושאים'!AR8:AV8,פרמטרים!$B$23:$F$23)/SUM(פרמטרים!$B$23:$F$23) | L8: =SUMPRODUCT('דירוגי נושאים'!AW8:BA8,פרמטרים!$B$23:$F$23)/SUM(פרמטרים!$B$23:$F$23) | M8: =(C8*פרמטרים!$B$4+D8*פרמטרים!$B$5+E8*פרמטרים!$B$6+F8*פרמטרים!$B$7+G8*פרמטרים!$B$8+H8*פרמטרים!$B$9+I8*פרמטרים!$B$10+J8*פרמטרים!$B$11+K8*פרמטרים!$B$12+L8*פרמטרים!$B$13)/SUM(פרמטרים!$B$4:$B$13) | N8: =SUMPRODUCT('דירוגי תכונות'!C8:F8,פרמטרים!$B$26:$E$26)/SUM(פרמטרים!$B$26:$E$26) | O8: =SUMPRODUCT('דירוגי תכונות'!G8:J8,פרמטרים!$B$26:$E$26)/SUM(פרמטרים!$B$26:$E$26) | P8: =SUMPRODUCT('דירוגי תכונות'!K8:N8,פרמטרים!$B$26:$E$26)/SUM(פרמטרים!$B$26:$E$26) | Q8: =SUMPRODUCT('דירוגי תכונות'!O8:R8,פרמטרים!$B$26:$E$26)/SUM(פרמטרים!$B$26:$E$26) | R8: =SUMPRODUCT('דירוגי תכונות'!S8:V8,פרמטרים!$B$26:$E$26)/SUM(פרמטרים!$B$26:$E$26) | S8: =(N8*פרמטרים!$B$16+O8*פרמטרים!$B$17+P8*פרמטרים!$B$18+Q8*פרמטרים!$B$19+R8*פרמטרים!$B$20)/SUM(פרמטרים!$B$16:$B$20) | T8: ='דירוגי נושאים'!C8 | U8: =(פרמטרים!$B$28*M8+(1-פרמטרים!$B$28)*S8)*(1-פרמטרים!$B$29*(5-T8)/4) | V8: =(U8-1)/4*100 | W8: =U8+ROW()/10000000 | X8: =RANK(W8,$W$2:$W$52)
A9: 8 | B9: ='דירוגי נושאים'!B9 | C9: =SUMPRODUCT('דירוגי נושאים'!D9:H9,פרמטרים!$B$23:$F$23)/SUM(פרמטרים!$B$23:$F$23) | D9: =SUMPRODUCT('דירוגי נושאים'!I9:M9,פרמטרים!$B$23:$F$23)/SUM(פרמטרים!$B$23:$F$23) | E9: =SUMPRODUCT('דירוגי נושאים'!N9:R9,פרמטרים!$B$23:$F$23)/SUM(פרמטרים!$B$23:$F$23) | F9: =SUMPRODUCT('דירוגי נושאים'!S9:W9,פרמטרים!$B$23:$F$23)/SUM(פרמטרים!$B$23:$F$23) | G9: =SUMPRODUCT('דירוגי נושאים'!X9:AB9,פרמטרים!$B$23:$F$23)/SUM(פרמטרים!$B$23:$F$23) | H9: =SUMPRODUCT('דירוגי נושאים'!AC9:AG9,פרמטרים!$B$23:$F$23)/SUM(פרמטרים!$B$23:$F$23) | I9: =SUMPRODUCT('דירוגי נושאים'!AH9:AL9,פרמטרים!$B$23:$F$23)/SUM(פרמטרים!$B$23:$F$23) | J9: =SUMPRODUCT('דירוגי נושאים'!AM9:AQ9,פרמטרים!$B$23:$F$23)/SUM(פרמטרים!$B$23:$F$23) | K9: =SUMPRODUCT('דירוגי נושאים'!AR9:AV9,פרמטרים!$B$23:$F$23)/SUM(פרמטרים!$B$23:$F$23) | L9: =SUMPRODUCT('דירוגי נושאים'!AW9:BA9,פרמטרים!$B$23:$F$23)/SUM(פרמטרים!$B$23:$F$23) | M9: =(C9*פרמטרים!$B$4+D9*פרמטרים!$B$5+E9*פרמטרים!$B$6+F9*פרמטרים!$B$7+G9*פרמטרים!$B$8+H9*פרמטרים!$B$9+I9*פרמטרים!$B$10+J9*פרמטרים!$B$11+K9*פרמטרים!$B$12+L9*פרמטרים!$B$13)/SUM(פרמטרים!$B$4:$B$13) | N9: =SUMPRODUCT('דירוגי תכונות'!C9:F9,פרמטרים!$B$26:$E$26)/SUM(פרמטרים!$B$26:$E$26) | O9: =SUMPRODUCT('דירוגי תכונות'!G9:J9,פרמטרים!$B$26:$E$26)/SUM(פרמטרים!$B$26:$E$26) | P9: =SUMPRODUCT('דירוגי תכונות'!K9:N9,פרמטרים!$B$26:$E$26)/SUM(פרמטרים!$B$26:$E$26) | Q9: =SUMPRODUCT('דירוגי תכונות'!O9:R9,פרמטרים!$B$26:$E$26)/SUM(פרמטרים!$B$26:$E$26) | R9: =SUMPRODUCT('דירוגי תכונות'!S9:V9,פרמטרים!$B$26:$E$26)/SUM(פרמטרים!$B$26:$E$26) | S9: =(N9*פרמטרים!$B$16+O9*פרמטרים!$B$17+P9*פרמטרים!$B$18+Q9*פרמטרים!$B$19+R9*פרמטרים!$B$20)/SUM(פרמטרים!$B$16:$B$20) | T9: ='דירוגי נושאים'!C9 | U9: =(פרמטרים!$B$28*M9+(1-פרמטרים!$B$28)*S9)*(1-פרמטרים!$B$29*(5-T9)/4) | V9: =(U9-1)/4*100 | W9: =U9+ROW()/10000000 | X9: =RANK(W9,$W$2:$W$52)
A10: 9 | B10: ='דירוגי נושאים'!B10 | C10: =SUMPRODUCT('דירוגי נושאים'!D10:H10,פרמטרים!$B$23:$F$23)/SUM(פרמטרים!$B$23:$F$23) | D10: =SUMPRODUCT('דירוגי נושאים'!I10:M10,פרמטרים!$B$23:$F$23)/SUM(פרמטרים!$B$23:$F$23) | E10: =SUMPRODUCT('דירוגי נושאים'!N10:R10,פרמטרים!$B$23:$F$23)/SUM(פרמטרים!$B$23:$F$23) | F10: =SUMPRODUCT('דירוגי נושאים'!S10:W10,פרמטרים!$B$23:$F$23)/SUM(פרמטרים!$B$23:$F$23) | G10: =SUMPRODUCT('דירוגי נושאים'!X10:AB10,פרמטרים!$B$23:$F$23)/SUM(פרמטרים!$B$23:$F$23) | H10: =SUMPRODUCT('דירוגי נושאים'!AC10:AG10,פרמטרים!$B$23:$F$23)/SUM(פרמטרים!$B$23:$F$23) | I10: =SUMPRODUCT('דירוגי נושאים'!AH10:AL10,פרמטרים!$B$23:$F$23)/SUM(פרמטרים!$B$23:$F$23) | J10: =SUMPRODUCT('דירוגי נושאים'!AM10:AQ10,פרמטרים!$B$23:$F$23)/SUM(פרמטרים!$B$23:$F$23) | K10: =SUMPRODUCT('דירוגי נושאים'!AR10:AV10,פרמטרים!$B$23:$F$23)/SUM(פרמטרים!$B$23:$F$23) | L10: =SUMPRODUCT('דירוגי נושאים'!AW10:BA10,פרמטרים!$B$23:$F$23)/SUM(פרמטרים!$B$23:$F$23) | M10: =(C10*פרמטרים!$B$4+D10*פרמטרים!$B$5+E10*פרמטרים!$B$6+F10*פרמטרים!$B$7+G10*פרמטרים!$B$8+H10*פרמטרים!$B$9+I10*פרמטרים!$B$10+J10*פרמטרים!$B$11+K10*פרמטרים!$B$12+L10*פרמטרים!$B$13)/SUM(פרמטרים!$B$4:$B$13) | N10: =SUMPRODUCT('דירוגי תכונות'!C10:F10,פרמטרים!$B$26:$E$26)/SUM(פרמטרים!$B$26:$E$26) | O10: =SUMPRODUCT('דירוגי תכונות'!G10:J10,פרמטרים!$B$26:$E$26)/SUM(פרמטרים!$B$26:$E$26) | P10: =SUMPRODUCT('דירוגי תכונות'!K10:N10,פרמטרים!$B$26:$E$26)/SUM(פרמטרים!$B$26:$E$26) | Q10: =SUMPRODUCT('דירוגי תכונות'!O10:R10,פרמטרים!$B$26:$E$26)/SUM(פרמטרים!$B$26:$E$26) | R10: =SUMPRODUCT('דירוגי תכונות'!S10:V10,פרמטרים!$B$26:$E$26)/SUM(פרמטרים!$B$26:$E$26) | S10: =(N10*פרמטרים!$B$16+O10*פרמטרים!$B$17+P10*פרמטרים!$B$18+Q10*פרמטרים!$B$19+R10*פרמטרים!$B$20)/SUM(פרמטרים!$B$16:$B$20) | T10: ='דירוגי נושאים'!C10 | U10: =(פרמטרים!$B$28*M10+(1-פרמטרים!$B$28)*S10)*(1-פרמטרים!$B$29*(5-T10)/4) | V10: =(U10-1)/4*100 | W10: =U10+ROW()/10000000 | X10: =RANK(W10,$W$2:$W$52)
A11: 10 | B11: ='דירוגי נושאים'!B11 | C11: =SUMPRODUCT('דירוגי נושאים'!D11:H11,פרמטרים!$B$23:$F$23)/SUM(פרמטרים!$B$23:$F$23) | D11: =SUMPRODUCT('דירוגי נושאים'!I11:M11,פרמטרים!$B$23:$F$23)/SUM(פרמטרים!$B$23:$F$23) | E11: =SUMPRODUCT('דירוגי נושאים'!N11:R11,פרמטרים!$B$23:$F$23)/SUM(פרמטרים!$B$23:$F$23) | F11: =SUMPRODUCT('דירוגי נושאים'!S11:W11,פרמטרים!$B$23:$F$23)/SUM(פרמטרים!$B$23:$F$23) | G11: =SUMPRODUCT('דירוגי נושאים'!X11:AB11,פרמטרים!$B$23:$F$23)/SUM(פרמטרים!$B$23:$F$23) | H11: =SUMPRODUCT('דירוגי נושאים'!AC11:AG11,פרמטרים!$B$23:$F$23)/SUM(פרמטרים!$B$23:$F$23) | I11: =SUMPRODUCT('דירוגי נושאים'!AH11:AL11,פרמטרים!$B$23:$F$23)/SUM(פרמטרים!$B$23:$F$23) | J11: =SUMPRODUCT('דירוגי נושאים'!AM11:AQ11,פרמטרים!$B$23:$F$23)/SUM(פרמטרים!$B$23:$F$23) | K11: =SUMPRODUCT('דירוגי נושאים'!AR11:AV11,פרמטרים!$B$23:$F$23)/SUM(פרמטרים!$B$23:$F$23) | L11: =SUMPRODUCT('דירוגי נושאים'!AW11:BA11,פרמטרים!$B$23:$F$23)/SUM(פרמטרים!$B$23:$F$23) | M11: =(C11*פרמטרים!$B$4+D11*פרמטרים!$B$5+E11*פרמטרים!$B$6+F11*פרמטרים!$B$7+G11*פרמטרים!$B$8+H11*פרמטרים!$B$9+I11*פרמטרים!$B$10+J11*פרמטרים!$B$11+K11*פרמטרים!$B$12+L11*פרמטרים!$B$13)/SUM(פרמטרים!$B$4:$B$13) | N11: =SUMPRODUCT('דירוגי תכונות'!C11:F11,פרמטרים!$B$26:$E$26)/SUM(פרמטרים!$B$26:$E$26) | O11: =SUMPRODUCT('דירוגי תכונות'!G11:J11,פרמטרים!$B$26:$E$26)/SUM(פרמטרים!$B$26:$E$26) | P11: =SUMPRODUCT('דירוגי תכונות'!K11:N11,פרמטרים!$B$26:$E$26)/SUM(פרמטרים!$B$26:$E$26) | Q11: =SUMPRODUCT('דירוגי תכונות'!O11:R11,פרמטרים!$B$26:$E$26)/SUM(פרמטרים!$B$26:$E$26) | R11: =SUMPRODUCT('דירוגי תכונות'!S11:V11,פרמטרים!$B$26:$E$26)/SUM(פרמטרים!$B$26:$E$26) | S11: =(N11*פרמטרים!$B$16+O11*פרמטרים!$B$17+P11*פרמטרים!$B$18+Q11*פרמטרים!$B$19+R11*פרמטרים!$B$20)/SUM(פרמטרים!$B$16:$B$20) | T11: ='דירוגי נושאים'!C11 | U11: =(פרמטרים!$B$28*M11+(1-פרמטרים!$B$28)*S11)*(1-פרמטרים!$B$29*(5-T11)/4) | V11: =(U11-1)/4*100 | W11: =U11+ROW()/10000000 | X11: =RANK(W11,$W$2:$W$52)
A12: 11 | B12: ='דירוגי נושאים'!B12 | C12: =SUMPRODUCT('דירוגי נושאים'!D12:H12,פרמטרים!$B$23:$F$23)/SUM(פרמטרים!$B$23:$F$23) | D12: =SUMPRODUCT('דירוגי נושאים'!I12:M12,פרמטרים!$B$23:$F$23)/SUM(פרמטרים!$B$23:$F$23) | E12: =SUMPRODUCT('דירוגי נושאים'!N12:R12,פרמטרים!$B$23:$F$23)/SUM(פרמטרים!$B$23:$F$23) | F12: =SUMPRODUCT('דירוגי נושאים'!S12:W12,פרמטרים!$B$23:$F$23)/SUM(פרמטרים!$B$23:$F$23) | G12: =SUMPRODUCT('דירוגי נושאים'!X12:AB12,פרמטרים!$B$23:$F$23)/SUM(פרמטרים!$B$23:$F$23) | H12: =SUMPRODUCT('דירוגי נושאים'!AC12:AG12,פרמטרים!$B$23:$F$23)/SUM(פרמטרים!$B$23:$F$23) | I12: =SUMPRODUCT('דירוגי נושאים'!AH12:AL12,פרמטרים!$B$23:$F$23)/SUM(פרמטרים!$B$23:$F$23) | J12: =SUMPRODUCT('דירוגי נושאים'!AM12:AQ12,פרמטרים!$B$23:$F$23)/SUM(פרמטרים!$B$23:$F$23) | K12: =SUMPRODUCT('דירוגי נושאים'!AR12:AV12,פרמטרים!$B$23:$F$23)/SUM(פרמטרים!$B$23:$F$23) | L12: =SUMPRODUCT('דירוגי נושאים'!AW12:BA12,פרמטרים!$B$23:$F$23)/SUM(פרמטרים!$B$23:$F$23) | M12: =(C12*פרמטרים!$B$4+D12*פרמטרים!$B$5+E12*פרמטרים!$B$6+F12*פרמטרים!$B$7+G12*פרמטרים!$B$8+H12*פרמטרים!$B$9+I12*פרמטרים!$B$10+J12*פרמטרים!$B$11+K12*פרמטרים!$B$12+L12*פרמטרים!$B$13)/SUM(פרמטרים!$B$4:$B$13) | N12: =SUMPRODUCT('דירוגי תכונות'!C12:F12,פרמטרים!$B$26:$E$26)/SUM(פרמטרים!$B$26:$E$26) | O12: =SUMPRODUCT('דירוגי תכונות'!G12:J12,פרמטרים!$B$26:$E$26)/SUM(פרמטרים!$B$26:$E$26) | P12: =SUMPRODUCT('דירוגי תכונות'!K12:N12,פרמטרים!$B$26:$E$26)/SUM(פרמטרים!$B$26:$E$26) | Q12: =SUMPRODUCT('דירוגי תכונות'!O12:R12,פרמטרים!$B$26:$E$26)/SUM(פרמטרים!$B$26:$E$26) | R12: =SUMPRODUCT('דירוגי תכונות'!S12:V12,פרמטרים!$B$26:$E$26)/SUM(פרמטרים!$B$26:$E$26) | S12: =(N12*פרמטרים!$B$16+O12*פרמטרים!$B$17+P12*פרמטרים!$B$18+Q12*פרמטרים!$B$19+R12*פרמטרים!$B$20)/SUM(פרמטרים!$B$16:$B$20) | T12: ='דירוגי נושאים'!C12 | U12: =(פרמטרים!$B$28*M12+(1-פרמטרים!$B$28)*S12)*(1-פרמטרים!$B$29*(5-T12)/4) | V12: =(U12-1)/4*100 | W12: =U12+ROW()/10000000 | X12: =RANK(W12,$W$2:$W$52)
A13: 12 | B13: ='דירוגי נושאים'!B13 | C13: =SUMPRODUCT('דירוגי נושאים'!D13:H13,פרמטרים!$B$23:$F$23)/SUM(פרמטרים!$B$23:$F$23) | D13: =SUMPRODUCT('דירוגי נושאים'!I13:M13,פרמטרים!$B$23:$F$23)/SUM(פרמטרים!$B$23:$F$23) | E13: =SUMPRODUCT('דירוגי נושאים'!N13:R13,פרמטרים!$B$23:$F$23)/SUM(פרמטרים!$B$23:$F$23) | F13: =SUMPRODUCT('דירוגי נושאים'!S13:W13,פרמטרים!$B$23:$F$23)/SUM(פרמטרים!$B$23:$F$23) | G13: =SUMPRODUCT('דירוגי נושאים'!X13:AB13,פרמטרים!$B$23:$F$23)/SUM(פרמטרים!$B$23:$F$23) | H13: =SUMPRODUCT('דירוגי נושאים'!AC13:AG13,פרמטרים!$B$23:$F$23)/SUM(פרמטרים!$B$23:$F$23) | I13: =SUMPRODUCT('דירוגי נושאים'!AH13:AL13,פרמטרים!$B$23:$F$23)/SUM(פרמטרים!$B$23:$F$23) | J13: =SUMPRODUCT('דירוגי נושאים'!AM13:AQ13,פרמטרים!$B$23:$F$23)/SUM(פרמטרים!$B$23:$F$23) | K13: =SUMPRODUCT('דירוגי נושאים'!AR13:AV13,פרמטרים!$B$23:$F$23)/SUM(פרמטרים!$B$23:$F$23) | L13: =SUMPRODUCT('דירוגי נושאים'!AW13:BA13,פרמטרים!$B$23:$F$23)/SUM(פרמטרים!$B$23:$F$23) | M13: =(C13*פרמטרים!$B$4+D13*פרמטרים!$B$5+E13*פרמטרים!$B$6+F13*פרמטרים!$B$7+G13*פרמטרים!$B$8+H13*פרמטרים!$B$9+I13*פרמטרים!$B$10+J13*פרמטרים!$B$11+K13*פרמטרים!$B$12+L13*פרמטרים!$B$13)/SUM(פרמטרים!$B$4:$B$13) | N13: =SUMPRODUCT('דירוגי תכונות'!C13:F13,פרמטרים!$B$26:$E$26)/SUM(פרמטרים!$B$26:$E$26) | O13: =SUMPRODUCT('דירוגי תכונות'!G13:J13,פרמטרים!$B$26:$E$26)/SUM(פרמטרים!$B$26:$E$26) | P13: =SUMPRODUCT('דירוגי תכונות'!K13:N13,פרמטרים!$B$26:$E$26)/SUM(פרמטרים!$B$26:$E$26) | Q13: =SUMPRODUCT('דירוגי תכונות'!O13:R13,פרמטרים!$B$26:$E$26)/SUM(פרמטרים!$B$26:$E$26) | R13: =SUMPRODUCT('דירוגי תכונות'!S13:V13,פרמטרים!$B$26:$E$26)/SUM(פרמטרים!$B$26:$E$26) | S13: =(N13*פרמטרים!$B$16+O13*פרמטרים!$B$17+P13*פרמטרים!$B$18+Q13*פרמטרים!$B$19+R13*פרמטרים!$B$20)/SUM(פרמטרים!$B$16:$B$20) | T13: ='דירוגי נושאים'!C13 | U13: =(פרמטרים!$B$28*M13+(1-פרמטרים!$B$28)*S13)*(1-פרמטרים!$B$29*(5-T13)/4) | V13: =(U13-1)/4*100 | W13: =U13+ROW()/10000000 | X13: =RANK(W13,$W$2:$W$52)
... A52: 51 | B52: ='דירוגי נושאים'!B52 | C52: =SUMPRODUCT('דירוגי נושאים'!D52:H52,פרמטרים!$B$23:$F$23)/SUM(פרמטרים!$B$23:$F$23) | D52: =SUMPRODUCT('דירוגי נושאים'!I52:M52,פרמטרים!$B$23:$F$23)/SUM(פרמטרים!$B$23:$F$23) | E52: =SUMPRODUCT('דירוגי נושאים'!N52:R52,פרמטרים!$B$23:$F$23)/SUM(פרמטרים!$B$23:$F$23) | F52: =SUMPRODUCT('דירוגי נושאים'!S52:W52,פרמטרים!$B$23:$F$23)/SUM(פרמטרים!$B$23:$F$23) | G52: =SUMPRODUCT('דירוגי נושאים'!X52:AB52,פרמטרים!$B$23:$F$23)/SUM(פרמטרים!$B$23:$F$23) | H52: =SUMPRODUCT('דירוגי נושאים'!AC52:AG52,פרמטרים!$B$23:$F$23)/SUM(פרמטרים!$B$23:$F$23) | I52: =SUMPRODUCT('דירוגי נושאים'!AH52:AL52,פרמטרים!$B$23:$F$23)/SUM(פרמטרים!$B$23:$F$23) | J52: =SUMPRODUCT('דירוגי נושאים'!AM52:AQ52,פרמטרים!$B$23:$F$23)/SUM(פרמטרים!$B$23:$F$23) | K52: =SUMPRODUCT('דירוגי נושאים'!AR52:AV52,פרמטרים!$B$23:$F$23)/SUM(פרמטרים!$B$23:$F$23) | L52: =SUMPRODUCT('דירוגי נושאים'!AW52:BA52,פרמטרים!$B$23:$F$23)/SUM(פרמטרים!$B$23:$F$23) | M52: =(C52*פרמטרים!$B$4+D52*פרמטרים!$B$5+E52*פרמטרים!$B$6+F52*פרמטרים!$B$7+G52*פרמטרים!$B$8+H52*פרמטרים!$B$9+I52*פרמטרים!$B$10+J52*פרמטרים!$B$11+K52*פרמטרים!$B$12+L52*פרמטרים!$B$13)/SUM(פרמטרים!$B$4:$B$13) | N52: =SUMPRODUCT('דירוגי תכונות'!C52:F52,פרמטרים!$B$26:$E$26)/SUM(פרמטרים!$B$26:$E$26) | O52: =SUMPRODUCT('דירוגי תכונות'!G52:J52,פרמטרים!$B$26:$E$26)/SUM(פרמטרים!$B$26:$E$26) | P52: =SUMPRODUCT('דירוגי תכונות'!K52:N52,פרמטרים!$B$26:$E$26)/SUM(פרמטרים!$B$26:$E$26) | Q52: =SUMPRODUCT('דירוגי תכונות'!O52:R52,פרמטרים!$B$26:$E$26)/SUM(פרמטרים!$B$26:$E$26) | R52: =SUMPRODUCT('דירוגי תכונות'!S52:V52,פרמטרים!$B$26:$E$26)/SUM(פרמטרים!$B$26:$E$26) | S52: =(N52*פרמטרים!$B$16+O52*פרמטרים!$B$17+P52*פרמטרים!$B$18+Q52*פרמטרים!$B$19+R52*פרמטרים!$B$20)/SUM(פרמטרים!$B$16:$B$20) | T52: ='דירוגי נושאים'!C52 | U52: =(פרמטרים!$B$28*M52+(1-פרמטרים!$B$28)*S52)*(1-פרמטרים!$B$29*(5-T52)/4) | V52: =(U52-1)/4*100 | W52: =U52+ROW()/10000000 | X52: =RANK(W52,$W$2:$W$52)

Sheet דירוג סופי
A1: דירוג המועמדים לפי הפרמטרים שלך (עדכני אוטומטית)
A3: מקום | B3: מועמד/ת | C3: ציון (0-100) | D3: ציון נושאים | E3: ציון תכונות | F3: ביסוס
A4: 1 | B4: =INDEX(חישוב!$B:$B,MATCH(LARGE(חישוב!$W$2:$W$52,1),חישוב!$W$2:$W$52,0)+1) | C4: =INDEX(חישוב!$V:$V,MATCH(LARGE(חישוב!$W$2:$W$52,1),חישוב!$W$2:$W$52,0)+1) | D4: =INDEX(חישוב!$M:$M,MATCH(LARGE(חישוב!$W$2:$W$52,1),חישוב!$W$2:$W$52,0)+1) | E4: =INDEX(חישוב!$S:$S,MATCH(LARGE(חישוב!$W$2:$W$52,1),חישוב!$W$2:$W$52,0)+1) | F4: =INDEX(חישוב!$T:$T,MATCH(LARGE(חישוב!$W$2:$W$52,1),חישוב!$W$2:$W$52,0)+1)
A5: 2 | B5: =INDEX(חישוב!$B:$B,MATCH(LARGE(חישוב!$W$2:$W$52,2),חישוב!$W$2:$W$52,0)+1) | C5: =INDEX(חישוב!$V:$V,MATCH(LARGE(חישוב!$W$2:$W$52,2),חישוב!$W$2:$W$52,0)+1) | D5: =INDEX(חישוב!$M:$M,MATCH(LARGE(חישוב!$W$2:$W$52,2),חישוב!$W$2:$W$52,0)+1) | E5: =INDEX(חישוב!$S:$S,MATCH(LARGE(חישוב!$W$2:$W$52,2),חישוב!$W$2:$W$52,0)+1) | F5: =INDEX(חישוב!$T:$T,MATCH(LARGE(חישוב!$W$2:$W$52,2),חישוב!$W$2:$W$52,0)+1)
A6: 3 | B6: =INDEX(חישוב!$B:$B,MATCH(LARGE(חישוב!$W$2:$W$52,3),חישוב!$W$2:$W$52,0)+1) | C6: =INDEX(חישוב!$V:$V,MATCH(LARGE(חישוב!$W$2:$W$52,3),חישוב!$W$2:$W$52,0)+1) | D6: =INDEX(חישוב!$M:$M,MATCH(LARGE(חישוב!$W$2:$W$52,3),חישוב!$W$2:$W$52,0)+1) | E6: =INDEX(חישוב!$S:$S,MATCH(LARGE(חישוב!$W$2:$W$52,3),חישוב!$W$2:$W$52,0)+1) | F6: =INDEX(חישוב!$T:$T,MATCH(LARGE(חישוב!$W$2:$W$52,3),חישוב!$W$2:$W$52,0)+1)
A7: 4 | B7: =INDEX(חישוב!$B:$B,MATCH(LARGE(חישוב!$W$2:$W$52,4),חישוב!$W$2:$W$52,0)+1) | C7: =INDEX(חישוב!$V:$V,MATCH(LARGE(חישוב!$W$2:$W$52,4),חישוב!$W$2:$W$52,0)+1) | D7: =INDEX(חישוב!$M:$M,MATCH(LARGE(חישוב!$W$2:$W$52,4),חישוב!$W$2:$W$52,0)+1) | E7: =INDEX(חישוב!$S:$S,MATCH(LARGE(חישוב!$W$2:$W$52,4),חישוב!$W$2:$W$52,0)+1) | F7: =INDEX(חישוב!$T:$T,MATCH(LARGE(חישוב!$W$2:$W$52,4),חישוב!$W$2:$W$52,0)+1)
A8: 5 | B8: =INDEX(חישוב!$B:$B,MATCH(LARGE(חישוב!$W$2:$W$52,5),חישוב!$W$2:$W$52,0)+1) | C8: =INDEX(חישוב!$V:$V,MATCH(LARGE(חישוב!$W$2:$W$52,5),חישוב!$W$2:$W$52,0)+1) | D8: =INDEX(חישוב!$M:$M,MATCH(LARGE(חישוב!$W$2:$W$52,5),חישוב!$W$2:$W$52,0)+1) | E8: =INDEX(חישוב!$S:$S,MATCH(LARGE(חישוב!$W$2:$W$52,5),חישוב!$W$2:$W$52,0)+1) | F8: =INDEX(חישוב!$T:$T,MATCH(LARGE(חישוב!$W$2:$W$52,5),חישוב!$W$2:$W$52,0)+1)
A9: 6 | B9: =INDEX(חישוב!$B:$B,MATCH(LARGE(חישוב!$W$2:$W$52,6),חישוב!$W$2:$W$52,0)+1) | C9: =INDEX(חישוב!$V:$V,MATCH(LARGE(חישוב!$W$2:$W$52,6),חישוב!$W$2:$W$52,0)+1) | D9: =INDEX(חישוב!$M:$M,MATCH(LARGE(חישוב!$W$2:$W$52,6),חישוב!$W$2:$W$52,0)+1) | E9: =INDEX(חישוב!$S:$S,MATCH(LARGE(חישוב!$W$2:$W$52,6),חישוב!$W$2:$W$52,0)+1) | F9: =INDEX(חישוב!$T:$T,MATCH(LARGE(חישוב!$W$2:$W$52,6),חישוב!$W$2:$W$52,0)+1)
A10: 7 | B10: =INDEX(חישוב!$B:$B,MATCH(LARGE(חישוב!$W$2:$W$52,7),חישוב!$W$2:$W$52,0)+1) | C10: =INDEX(חישוב!$V:$V,MATCH(LARGE(חישוב!$W$2:$W$52,7),חישוב!$W$2:$W$52,0)+1) | D10: =INDEX(חישוב!$M:$M,MATCH(LARGE(חישוב!$W$2:$W$52,7),חישוב!$W$2:$W$52,0)+1) | E10: =INDEX(חישוב!$S:$S,MATCH(LARGE(חישוב!$W$2:$W$52,7),חישוב!$W$2:$W$52,0)+1) | F10: =INDEX(חישוב!$T:$T,MATCH(LARGE(חישוב!$W$2:$W$52,7),חישוב!$W$2:$W$52,0)+1)
A11: 8 | B11: =INDEX(חישוב!$B:$B,MATCH(LARGE(חישוב!$W$2:$W$52,8),חישוב!$W$2:$W$52,0)+1) | C11: =INDEX(חישוב!$V:$V,MATCH(LARGE(חישוב!$W$2:$W$52,8),חישוב!$W$2:$W$52,0)+1) | D11: =INDEX(חישוב!$M:$M,MATCH(LARGE(חישוב!$W$2:$W$52,8),חישוב!$W$2:$W$52,0)+1) | E11: =INDEX(חישוב!$S:$S,MATCH(LARGE(חישוב!$W$2:$W$52,8),חישוב!$W$2:$W$52,0)+1) | F11: =INDEX(חישוב!$T:$T,MATCH(LARGE(חישוב!$W$2:$W$52,8),חישוב!$W$2:$W$52,0)+1)
A12: 9 | B12: =INDEX(חישוב!$B:$B,MATCH(LARGE(חישוב!$W$2:$W$52,9),חישוב!$W$2:$W$52,0)+1) | C12: =INDEX(חישוב!$V:$V,MATCH(LARGE(חישוב!$W$2:$W$52,9),חישוב!$W$2:$W$52,0)+1) | D12: =INDEX(חישוב!$M:$M,MATCH(LARGE(חישוב!$W$2:$W$52,9),חישוב!$W$2:$W$52,0)+1) | E12: =INDEX(חישוב!$S:$S,MATCH(LARGE(חישוב!$W$2:$W$52,9),חישוב!$W$2:$W$52,0)+1) | F12: =INDEX(חישוב!$T:$T,MATCH(LARGE(חישוב!$W$2:$W$52,9),חישוב!$W$2:$W$52,0)+1)
A13: 10 | B13: =INDEX(חישוב!$B:$B,MATCH(LARGE(חישוב!$W$2:$W$52,10),חישוב!$W$2:$W$52,0)+1) | C13: =INDEX(חישוב!$V:$V,MATCH(LARGE(חישוב!$W$2:$W$52,10),חישוב!$W$2:$W$52,0)+1) | D13: =INDEX(חישוב!$M:$M,MATCH(LARGE(חישוב!$W$2:$W$52,10),חישוב!$W$2:$W$52,0)+1) | E13: =INDEX(חישוב!$S:$S,MATCH(LARGE(חישוב!$W$2:$W$52,10),חישוב!$W$2:$W$52,0)+1) | F13: =INDEX(חישוב!$T:$T,MATCH(LARGE(חישוב!$W$2:$W$52,10),חישוב!$W$2:$W$52,0)+1)
A14: 11 | B14: =INDEX(חישוב!$B:$B,MATCH(LARGE(חישוב!$W$2:$W$52,11),חישוב!$W$2:$W$52,0)+1) | C14: =INDEX(חישוב!$V:$V,MATCH(LARGE(חישוב!$W$2:$W$52,11),חישוב!$W$2:$W$52,0)+1) | D14: =INDEX(חישוב!$M:$M,MATCH(LARGE(חישוב!$W$2:$W$52,11),חישוב!$W$2:$W$52,0)+1) | E14: =INDEX(חישוב!$S:$S,MATCH(LARGE(חישוב!$W$2:$W$52,11),חישוב!$W$2:$W$52,0)+1) | F14: =INDEX(חישוב!$T:$T,MATCH(LARGE(חישוב!$W$2:$W$52,11),חישוב!$W$2:$W$52,0)+1)
A15: 12 | B15: =INDEX(חישוב!$B:$B,MATCH(LARGE(חישוב!$W$2:$W$52,12),חישוב!$W$2:$W$52,0)+1) | C15: =INDEX(חישוב!$V:$V,MATCH(LARGE(חישוב!$W$2:$W$52,12),חישוב!$W$2:$W$52,0)+1) | D15: =INDEX(חישוב!$M:$M,MATCH(LARGE(חישוב!$W$2:$W$52,12),חישוב!$W$2:$W$52,0)+1) | E15: =INDEX(חישוב!$S:$S,MATCH(LARGE(חישוב!$W$2:$W$52,12),חישוב!$W$2:$W$52,0)+1) | F15: =INDEX(חישוב!$T:$T,MATCH(LARGE(חישוב!$W$2:$W$52,12),חישוב!$W$2:$W$52,0)+1)
A16: 13 | B16: =INDEX(חישוב!$B:$B,MATCH(LARGE(חישוב!$W$2:$W$52,13),חישוב!$W$2:$W$52,0)+1) | C16: =INDEX(חישוב!$V:$V,MATCH(LARGE(חישוב!$W$2:$W$52,13),חישוב!$W$2:$W$52,0)+1) | D16: =INDEX(חישוב!$M:$M,MATCH(LARGE(חישוב!$W$2:$W$52,13),חישוב!$W$2:$W$52,0)+1) | E16: =INDEX(חישוב!$S:$S,MATCH(LARGE(חישוב!$W$2:$W$52,13),חישוב!$W$2:$W$52,0)+1) | F16: =INDEX(חישוב!$T:$T,MATCH(LARGE(חישוב!$W$2:$W$52,13),חישוב!$W$2:$W$52,0)+1)
A17: 14 | B17: =INDEX(חישוב!$B:$B,MATCH(LARGE(חישוב!$W$2:$W$52,14),חישוב!$W$2:$W$52,0)+1) | C17: =INDEX(חישוב!$V:$V,MATCH(LARGE(חישוב!$W$2:$W$52,14),חישוב!$W$2:$W$52,0)+1) | D17: =INDEX(חישוב!$M:$M,MATCH(LARGE(חישוב!$W$2:$W$52,14),חישוב!$W$2:$W$52,0)+1) | E17: =INDEX(חישוב!$S:$S,MATCH(LARGE(חישוב!$W$2:$W$52,14),חישוב!$W$2:$W$52,0)+1) | F17: =INDEX(חישוב!$T:$T,MATCH(LARGE(חישוב!$W$2:$W$52,14),חישוב!$W$2:$W$52,0)+1)
A18: 15 | B18: =INDEX(חישוב!$B:$B,MATCH(LARGE(חישוב!$W$2:$W$52,15),חישוב!$W$2:$W$52,0)+1) | C18: =INDEX(חישוב!$V:$V,MATCH(LARGE(חישוב!$W$2:$W$52,15),חישוב!$W$2:$W$52,0)+1) | D18: =INDEX(חישוב!$M:$M,MATCH(LARGE(חישוב!$W$2:$W$52,15),חישוב!$W$2:$W$52,0)+1) | E18: =INDEX(חישוב!$S:$S,MATCH(LARGE(חישוב!$W$2:$W$52,15),חישוב!$W$2:$W$52,0)+1) | F18: =INDEX(חישוב!$T:$T,MATCH(LARGE(חישוב!$W$2:$W$52,15),חישוב!$W$2:$W$52,0)+1)
A19: 16 | B19: =INDEX(חישוב!$B:$B,MATCH(LARGE(חישוב!$W$2:$W$52,16),חישוב!$W$2:$W$52,0)+1) | C19: =INDEX(חישוב!$V:$V,MATCH(LARGE(חישוב!$W$2:$W$52,16),חישוב!$W$2:$W$52,0)+1) | D19: =INDEX(חישוב!$M:$M,MATCH(LARGE(חישוב!$W$2:$W$52,16),חישוב!$W$2:$W$52,0)+1) | E19: =INDEX(חישוב!$S:$S,MATCH(LARGE(חישוב!$W$2:$W$52,16),חישוב!$W$2:$W$52,0)+1) | F19: =INDEX(חישוב!$T:$T,MATCH(LARGE(חישוב!$W$2:$W$52,16),חישוב!$W$2:$W$52,0)+1)
A20: 17 | B20: =INDEX(חישוב!$B:$B,MATCH(LARGE(חישוב!$W$2:$W$52,17),חישוב!$W$2:$W$52,0)+1) | C20: =INDEX(חישוב!$V:$V,MATCH(LARGE(חישוב!$W$2:$W$52,17),חישוב!$W$2:$W$52,0)+1) | D20: =INDEX(חישוב!$M:$M,MATCH(LARGE(חישוב!$W$2:$W$52,17),חישוב!$W$2:$W$52,0)+1) | E20: =INDEX(חישוב!$S:$S,MATCH(LARGE(חישוב!$W$2:$W$52,17),חישוב!$W$2:$W$52,0)+1) | F20: =INDEX(חישוב!$T:$T,MATCH(LARGE(חישוב!$W$2:$W$52,17),חישוב!$W$2:$W$52,0)+1)
A21: 18 | B21: =INDEX(חישוב!$B:$B,MATCH(LARGE(חישוב!$W$2:$W$52,18),חישוב!$W$2:$W$52,0)+1) | C21: =INDEX(חישוב!$V:$V,MATCH(LARGE(חישוב!$W$2:$W$52,18),חישוב!$W$2:$W$52,0)+1) | D21: =INDEX(חישוב!$M:$M,MATCH(LARGE(חישוב!$W$2:$W$52,18),חישוב!$W$2:$W$52,0)+1) | E21: =INDEX(חישוב!$S:$S,MATCH(LARGE(חישוב!$W$2:$W$52,18),חישוב!$W$2:$W$52,0)+1) | F21: =INDEX(חישוב!$T:$T,MATCH(LARGE(חישוב!$W$2:$W$52,18),חישוב!$W$2:$W$52,0)+1)
A22: 19 | B22: =INDEX(חישוב!$B:$B,MATCH(LARGE(חישוב!$W$2:$W$52,19),חישוב!$W$2:$W$52,0)+1) | C22: =INDEX(חישוב!$V:$V,MATCH(LARGE(חישוב!$W$2:$W$52,19),חישוב!$W$2:$W$52,0)+1) | D22: =INDEX(חישוב!$M:$M,MATCH(LARGE(חישוב!$W$2:$W$52,19),חישוב!$W$2:$W$52,0)+1) | E22: =INDEX(חישוב!$S:$S,MATCH(LARGE(חישוב!$W$2:$W$52,19),חישוב!$W$2:$W$52,0)+1) | F22: =INDEX(חישוב!$T:$T,MATCH(LARGE(חישוב!$W$2:$W$52,19),חישוב!$W$2:$W$52,0)+1)
A23: 20 | B23: =INDEX(חישוב!$B:$B,MATCH(LARGE(חישוב!$W$2:$W$52,20),חישוב!$W$2:$W$52,0)+1) | C23: =INDEX(חישוב!$V:$V,MATCH(LARGE(חישוב!$W$2:$W$52,20),חישוב!$W$2:$W$52,0)+1) | D23: =INDEX(חישוב!$M:$M,MATCH(LARGE(חישוב!$W$2:$W$52,20),חישוב!$W$2:$W$52,0)+1) | E23: =INDEX(חישוב!$S:$S,MATCH(LARGE(חישוב!$W$2:$W$52,20),חישוב!$W$2:$W$52,0)+1) | F23: =INDEX(חישוב!$T:$T,MATCH(LARGE(חישוב!$W$2:$W$52,20),חישוב!$W$2:$W$52,0)+1)
A24: 21 | B24: =INDEX(חישוב!$B:$B,MATCH(LARGE(חישוב!$W$2:$W$52,21),חישוב!$W$2:$W$52,0)+1) | C24: =INDEX(חישוב!$V:$V,MATCH(LARGE(חישוב!$W$2:$W$52,21),חישוב!$W$2:$W$52,0)+1) | D24: =INDEX(חישוב!$M:$M,MATCH(LARGE(חישוב!$W$2:$W$52,21),חישוב!$W$2:$W$52,0)+1) | E24: =INDEX(חישוב!$S:$S,MATCH(LARGE(חישוב!$W$2:$W$52,21),חישוב!$W$2:$W$52,0)+1) | F24: =INDEX(חישוב!$T:$T,MATCH(LARGE(חישוב!$W$2:$W$52,21),חישוב!$W$2:$W$52,0)+1)
A25: 22 | B25: =INDEX(חישוב!$B:$B,MATCH(LARGE(חישוב!$W$2:$W$52,22),חישוב!$W$2:$W$52,0)+1) | C25: =INDEX(חישוב!$V:$V,MATCH(LARGE(חישוב!$W$2:$W$52,22),חישוב!$W$2:$W$52,0)+1) | D25: =INDEX(חישוב!$M:$M,MATCH(LARGE(חישוב!$W$2:$W$52,22),חישוב!$W$2:$W$52,0)+1) | E25: =INDEX(חישוב!$S:$S,MATCH(LARGE(חישוב!$W$2:$W$52,22),חישוב!$W$2:$W$52,0)+1) | F25: =INDEX(חישוב!$T:$T,MATCH(LARGE(חישוב!$W$2:$W$52,22),חישוב!$W$2:$W$52,0)+1)
A26: 23 | B26: =INDEX(חישוב!$B:$B,MATCH(LARGE(חישוב!$W$2:$W$52,23),חישוב!$W$2:$W$52,0)+1) | C26: =INDEX(חישוב!$V:$V,MATCH(LARGE(חישוב!$W$2:$W$52,23),חישוב!$W$2:$W$52,0)+1) | D26: =INDEX(חישוב!$M:$M,MATCH(LARGE(חישוב!$W$2:$W$52,23),חישוב!$W$2:$W$52,0)+1) | E26: =INDEX(חישוב!$S:$S,MATCH(LARGE(חישוב!$W$2:$W$52,23),חישוב!$W$2:$W$52,0)+1) | F26: =INDEX(חישוב!$T:$T,MATCH(LARGE(חישוב!$W$2:$W$52,23),חישוב!$W$2:$W$52,0)+1)
A27: 24 | B27: =INDEX(חישוב!$B:$B,MATCH(LARGE(חישוב!$W$2:$W$52,24),חישוב!$W$2:$W$52,0)+1) | C27: =INDEX(חישוב!$V:$V,MATCH(LARGE(חישוב!$W$2:$W$52,24),חישוב!$W$2:$W$52,0)+1) | D27: =INDEX(חישוב!$M:$M,MATCH(LARGE(חישוב!$W$2:$W$52,24),חישוב!$W$2:$W$52,0)+1) | E27: =INDEX(חישוב!$S:$S,MATCH(LARGE(חישוב!$W$2:$W$52,24),חישוב!$W$2:$W$52,0)+1) | F27: =INDEX(חישוב!$T:$T,MATCH(LARGE(חישוב!$W$2:$W$52,24),חישוב!$W$2:$W$52,0)+1)
A28: 25 | B28: =INDEX(חישוב!$B:$B,MATCH(LARGE(חישוב!$W$2:$W$52,25),חישוב!$W$2:$W$52,0)+1) | C28: =INDEX(חישוב!$V:$V,MATCH(LARGE(חישוב!$W$2:$W$52,25),חישוב!$W$2:$W$52,0)+1) | D28: =INDEX(חישוב!$M:$M,MATCH(LARGE(חישוב!$W$2:$W$52,25),חישוב!$W$2:$W$52,0)+1) | E28: =INDEX(חישוב!$S:$S,MATCH(LARGE(חישוב!$W$2:$W$52,25),חישוב!$W$2:$W$52,0)+1) | F28: =INDEX(חישוב!$T:$T,MATCH(LARGE(חישוב!$W$2:$W$52,25),חישוב!$W$2:$W$52,0)+1)
A29: 26 | B29: =INDEX(חישוב!$B:$B,MATCH(LARGE(חישוב!$W$2:$W$52,26),חישוב!$W$2:$W$52,0)+1) | C29: =INDEX(חישוב!$V:$V,MATCH(LARGE(חישוב!$W$2:$W$52,26),חישוב!$W$2:$W$52,0)+1) | D29: =INDEX(חישוב!$M:$M,MATCH(LARGE(חישוב!$W$2:$W$52,26),חישוב!$W$2:$W$52,0)+1) | E29: =INDEX(חישוב!$S:$S,MATCH(LARGE(חישוב!$W$2:$W$52,26),חישוב!$W$2:$W$52,0)+1) | F29: =INDEX(חישוב!$T:$T,MATCH(LARGE(חישוב!$W$2:$W$52,26),חישוב!$W$2:$W$52,0)+1)
A30: 27 | B30: =INDEX(חישוב!$B:$B,MATCH(LARGE(חישוב!$W$2:$W$52,27),חישוב!$W$2:$W$52,0)+1) | C30: =INDEX(חישוב!$V:$V,MATCH(LARGE(חישוב!$W$2:$W$52,27),חישוב!$W$2:$W$52,0)+1) | D30: =INDEX(חישוב!$M:$M,MATCH(LARGE(חישוב!$W$2:$W$52,27),חישוב!$W$2:$W$52,0)+1) | E30: =INDEX(חישוב!$S:$S,MATCH(LARGE(חישוב!$W$2:$W$52,27),חישוב!$W$2:$W$52,0)+1) | F30: =INDEX(חישוב!$T:$T,MATCH(LARGE(חישוב!$W$2:$W$52,27),חישוב!$W$2:$W$52,0)+1)
A31: 28 | B31: =INDEX(חישוב!$B:$B,MATCH(LARGE(חישוב!$W$2:$W$52,28),חישוב!$W$2:$W$52,0)+1) | C31: =INDEX(חישוב!$V:$V,MATCH(LARGE(חישוב!$W$2:$W$52,28),חישוב!$W$2:$W$52,0)+1) | D31: =INDEX(חישוב!$M:$M,MATCH(LARGE(חישוב!$W$2:$W$52,28),חישוב!$W$2:$W$52,0)+1) | E31: =INDEX(חישוב!$S:$S,MATCH(LARGE(חישוב!$W$2:$W$52,28),חישוב!$W$2:$W$52,0)+1) | F31: =INDEX(חישוב!$T:$T,MATCH(LARGE(חישוב!$W$2:$W$52,28),חישוב!$W$2:$W$52,0)+1)
A32: 29 | B32: =INDEX(חישוב!$B:$B,MATCH(LARGE(חישוב!$W$2:$W$52,29),חישוב!$W$2:$W$52,0)+1) | C32: =INDEX(חישוב!$V:$V,MATCH(LARGE(חישוב!$W$2:$W$52,29),חישוב!$W$2:$W$52,0)+1) | D32: =INDEX(חישוב!$M:$M,MATCH(LARGE(חישוב!$W$2:$W$52,29),חישוב!$W$2:$W$52,0)+1) | E32: =INDEX(חישוב!$S:$S,MATCH(LARGE(חישוב!$W$2:$W$52,29),חישוב!$W$2:$W$52,0)+1) | F32: =INDEX(חישוב!$T:$T,MATCH(LARGE(חישוב!$W$2:$W$52,29),חישוב!$W$2:$W$52,0)+1)
A33: 30 | B33: =INDEX(חישוב!$B:$B,MATCH(LARGE(חישוב!$W$2:$W$52,30),חישוב!$W$2:$W$52,0)+1) | C33: =INDEX(חישוב!$V:$V,MATCH(LARGE(חישוב!$W$2:$W$52,30),חישוב!$W$2:$W$52,0)+1) | D33: =INDEX(חישוב!$M:$M,MATCH(LARGE(חישוב!$W$2:$W$52,30),חישוב!$W$2:$W$52,0)+1) | E33: =INDEX(חישוב!$S:$S,MATCH(LARGE(חישוב!$W$2:$W$52,30),חישוב!$W$2:$W$52,0)+1) | F33: =INDEX(חישוב!$T:$T,MATCH(LARGE(חישוב!$W$2:$W$52,30),חישוב!$W$2:$W$52,0)+1)
A34: 31 | B34: =INDEX(חישוב!$B:$B,MATCH(LARGE(חישוב!$W$2:$W$52,31),חישוב!$W$2:$W$52,0)+1) | C34: =INDEX(חישוב!$V:$V,MATCH(LARGE(חישוב!$W$2:$W$52,31),חישוב!$W$2:$W$52,0)+1) | D34: =INDEX(חישוב!$M:$M,MATCH(LARGE(חישוב!$W$2:$W$52,31),חישוב!$W$2:$W$52,0)+1) | E34: =INDEX(חישוב!$S:$S,MATCH(LARGE(חישוב!$W$2:$W$52,31),חישוב!$W$2:$W$52,0)+1) | F34: =INDEX(חישוב!$T:$T,MATCH(LARGE(חישוב!$W$2:$W$52,31),חישוב!$W$2:$W$52,0)+1)
A35: 32 | B35: =INDEX(חישוב!$B:$B,MATCH(LARGE(חישוב!$W$2:$W$52,32),חישוב!$W$2:$W$52,0)+1) | C35: =INDEX(חישוב!$V:$V,MATCH(LARGE(חישוב!$W$2:$W$52,32),חישוב!$W$2:$W$52,0)+1) | D35: =INDEX(חישוב!$M:$M,MATCH(LARGE(חישוב!$W$2:$W$52,32),חישוב!$W$2:$W$52,0)+1) | E35: =INDEX(חישוב!$S:$S,MATCH(LARGE(חישוב!$W$2:$W$52,32),חישוב!$W$2:$W$52,0)+1) | F35: =INDEX(חישוב!$T:$T,MATCH(LARGE(חישוב!$W$2:$W$52,32),חישוב!$W$2:$W$52,0)+1)
A36: 33 | B36: =INDEX(חישוב!$B:$B,MATCH(LARGE(חישוב!$W$2:$W$52,33),חישוב!$W$2:$W$52,0)+1) | C36: =INDEX(חישוב!$V:$V,MATCH(LARGE(חישוב!$W$2:$W$52,33),חישוב!$W$2:$W$52,0)+1) | D36: =INDEX(חישוב!$M:$M,MATCH(LARGE(חישוב!$W$2:$W$52,33),חישוב!$W$2:$W$52,0)+1) | E36: =INDEX(חישוב!$S:$S,MATCH(LARGE(חישוב!$W$2:$W$52,33),חישוב!$W$2:$W$52,0)+1) | F36: =INDEX(חישוב!$T:$T,MATCH(LARGE(חישוב!$W$2:$W$52,33),חישוב!$W$2:$W$52,0)+1)
A37: 34 | B37: =INDEX(חישוב!$B:$B,MATCH(LARGE(חישוב!$W$2:$W$52,34),חישוב!$W$2:$W$52,0)+1) | C37: =INDEX(חישוב!$V:$V,MATCH(LARGE(חישוב!$W$2:$W$52,34),חישוב!$W$2:$W$52,0)+1) | D37: =INDEX(חישוב!$M:$M,MATCH(LARGE(חישוב!$W$2:$W$52,34),חישוב!$W$2:$W$52,0)+1) | E37: =INDEX(חישוב!$S:$S,MATCH(LARGE(חישוב!$W$2:$W$52,34),חישוב!$W$2:$W$52,0)+1) | F37: =INDEX(חישוב!$T:$T,MATCH(LARGE(חישוב!$W$2:$W$52,34),חישוב!$W$2:$W$52,0)+1)
A38: 35 | B38: =INDEX(חישוב!$B:$B,MATCH(LARGE(חישוב!$W$2:$W$52,35),חישוב!$W$2:$W$52,0)+1) | C38: =INDEX(חישוב!$V:$V,MATCH(LARGE(חישוב!$W$2:$W$52,35),חישוב!$W$2:$W$52,0)+1) | D38: =INDEX(חישוב!$M:$M,MATCH(LARGE(חישוב!$W$2:$W$52,35),חישוב!$W$2:$W$52,0)+1) | E38: =INDEX(חישוב!$S:$S,MATCH(LARGE(חישוב!$W$2:$W$52,35),חישוב!$W$2:$W$52,0)+1) | F38: =INDEX(חישוב!$T:$T,MATCH(LARGE(חישוב!$W$2:$W$52,35),חישוב!$W$2:$W$52,0)+1)
A39: 36 | B39: =INDEX(חישוב!$B:$B,MATCH(LARGE(חישוב!$W$2:$W$52,36),חישוב!$W$2:$W$52,0)+1) | C39: =INDEX(חישוב!$V:$V,MATCH(LARGE(חישוב!$W$2:$W$52,36),חישוב!$W$2:$W$52,0)+1) | D39: =INDEX(חישוב!$M:$M,MATCH(LARGE(חישוב!$W$2:$W$52,36),חישוב!$W$2:$W$52,0)+1) | E39: =INDEX(חישוב!$S:$S,MATCH(LARGE(חישוב!$W$2:$W$52,36),חישוב!$W$2:$W$52,0)+1) | F39: =INDEX(חישוב!$T:$T,MATCH(LARGE(חישוב!$W$2:$W$52,36),חישוב!$W$2:$W$52,0)+1)
A40: 37 | B40: =INDEX(חישוב!$B:$B,MATCH(LARGE(חישוב!$W$2:$W$52,37),חישוב!$W$2:$W$52,0)+1) | C40: =INDEX(חישוב!$V:$V,MATCH(LARGE(חישוב!$W$2:$W$52,37),חישוב!$W$2:$W$52,0)+1) | D40: =INDEX(חישוב!$M:$M,MATCH(LARGE(חישוב!$W$2:$W$52,37),חישוב!$W$2:$W$52,0)+1) | E40: =INDEX(חישוב!$S:$S,MATCH(LARGE(חישוב!$W$2:$W$52,37),חישוב!$W$2:$W$52,0)+1) | F40: =INDEX(חישוב!$T:$T,MATCH(LARGE(חישוב!$W$2:$W$52,37),חישוב!$W$2:$W$52,0)+1)
A41: 38 | B41: =INDEX(חישוב!$B:$B,MATCH(LARGE(חישוב!$W$2:$W$52,38),חישוב!$W$2:$W$52,0)+1) | C41: =INDEX(חישוב!$V:$V,MATCH(LARGE(חישוב!$W$2:$W$52,38),חישוב!$W$2:$W$52,0)+1) | D41: =INDEX(חישוב!$M:$M,MATCH(LARGE(חישוב!$W$2:$W$52,38),חישוב!$W$2:$W$52,0)+1) | E41: =INDEX(חישוב!$S:$S,MATCH(LARGE(חישוב!$W$2:$W$52,38),חישוב!$W$2:$W$52,0)+1) | F41: =INDEX(חישוב!$T:$T,MATCH(LARGE(חישוב!$W$2:$W$52,38),חישוב!$W$2:$W$52,0)+1)
...
